Workbook
Name \0: #REF!
Name \0: #REF!
Name \0: #REF!
Name \0: #REF!
Name \0: #REF!
Name \A: #REF!
Name \A: #REF!
Name \A: #REF!
Name \A: #REF!
Name \A: #REF!
Name \B: #REF!
Name \B: #REF!
Name \B: #REF!
Name \B: #REF!
Name \B: #REF!
Name \C: #REF!
Name \C: #REF!
Name \C: #REF!
Name \C: #REF!
Name \C: #REF!
Name \CLEARDATA: #REF!
Name \CLEARDATA: #REF!
Name \CLEARDATA: #REF!
Name \CLEARDATA: #REF!
Name \CLEARDATA: #REF!
Name \D: #REF!
Name \D: #REF!
Name \D: #REF!
Name \D: #REF!
Name \D: #REF!
Name \DELETE: #REF!
Name \DELETE: #REF!
Name \DELETE: #REF!
Name \DELETE: #REF!
Name \DELETE: #REF!
Name \e: #REF!
Name \e: #REF!
Name \e: #REF!
Name \e: #REF!
Name \e: #REF!
Name \I: #REF!
Name \I: #REF!
Name \I: #REF!
Name \I: #REF!
Name \I: #REF!
Name \INIT: #REF!
Name \INIT: #REF!
Name \INIT: #REF!
Name \INIT: #REF!
Name \INIT: #REF!
Name \l: '[1]CH Qs Form'!$D$420
Name \MAINPROC: #REF!
Name \MAINPROC: #REF!
Name \MAINPROC: #REF!
Name \MAINPROC: #REF!
Name \MAINPROC: #REF!
Name \o: '[1]CH Qs Form'!$D$422
Name \P: #REF!
Name \P: #REF!
Name \P: #REF!

Sheet 原始參數_115
B1: 114年年化達成率 | C1: 115年成長目標 | D1: 成長目標計算公式 | E1: 114年年化達成率 | F1: 預估實績參數 | G1: 分行目標參數
A2: =_xlfn.CONCAT("TYPE_", I2) -> TYPE_9 | B2: 未達75% | C2: 114年分行目標成長15% | D2: 分行目標*115% | E2: 0 | F2: 1 | G2: 1.15 | H2: 1 | I2: 9
A3: =_xlfn.CONCAT("TYPE_", I3) -> TYPE_8 | B3: 75%以上，未達90% | C3: 114年分行目標成長10% | D3: 分行目標*110% | E3: 0.75 | F3: 1 | G3: 1.1 | H3: 2 | I3: 8
A4: =_xlfn.CONCAT("TYPE_", I4) -> TYPE_7 | B4: 90%以上，未達100% | C4: 114年分行目標成長5% | D4: 分行目標*105% | E4: 0.9 | F4: 1 | G4: 1.05 | H4: 3 | I4: 7
A5: =_xlfn.CONCAT("TYPE_", I5) -> TYPE_6 | B5: 100%以上，未達110% | C5: 114年預估實績成長5% | D5: 預估實績*105% | E5: 1 | F5: 1.05 | G5: 1 | H5: 4 | I5: 6
A6: =_xlfn.CONCAT("TYPE_", I6) -> TYPE_5 | B6: 110%以上，未達120% | C6: 114年預估實績成長3% | D6: 預估實績*103% | E6: 1.1 | F6: 1.03 | G6: 1 | H6: 5 | I6: 5
A7: =_xlfn.CONCAT("TYPE_", I7) -> TYPE_4 | B7: 120%以上，未達130% | C7: 114年預估實績成長1% | D7: 預估實績*101% | E7: 1.2 | F7: 1.01 | G7: 1 | H7: 6 | I7: 4
A8: =_xlfn.CONCAT("TYPE_", I8) -> TYPE_3 | B8: 130%以上，未達150% | C8: 114年預估實績打9折 | D8: 預估實績*90% | E8: 1.3 | F8: 0.9 | G8: 1 | H8: 7 | I8: 3
A9: =_xlfn.CONCAT("TYPE_", I9) -> TYPE_2 | B9: 150%以上，未達200% | C9: 114年預估實績打8折 | D9: 預估實績*80% | E9: 1.5 | F9: 0.8 | G9: 1 | H9: 8 | I9: 2
A10: =_xlfn.CONCAT("TYPE_", I10) -> TYPE_1 | B10: 200%以上 | C10: 114年預估實績打7折 | D10: 預估實績*70% | E10: 2 | F10: 0.7 | G10: 1 | H10: 9 | I10: 1

Sheet 財管手收比較表_值
A1: 116年營業單位財富管理業務手續費收入目標暨115年目標及實績成長比較表
T2: 單位:新臺幣元/%
A3: 序號 | B3: 通路中心 | C3: 單位代號 | D3: 單位名稱 | E3: 115年 年化實績 | F3: 115年 目標 | G3: 115年 年化達成率 | H3: 115年 年化達成率 成長目標類型 | I3: 116年 原始規則 目標參數 | J3: 116年 原始規則 目標數 | K3: 115年 年化達成率 成長目標類型 | L3: 116年 調整規則 目標參數 | M3: 114年達成情形之成長目標(95%) | N3: 各營業單位綜合指標之目標(5%) | O3: 115年 目標 | P3: 114年 目標 | Q3: 114年 年化實績 | R3: 114年 年化達成率 | S3: 115年目標 較114年目標 成長率 | T3: 115年目標 較114年實績 成長率 | U3: 115年 客群經營目標 | V3: 115年 前版目標 | W3: 115年 目標較前版差異
E4: (A) | F4: (B) | G4: (C) | H4: (D) | I4: (E) | J4: (F) | K4: (D) | L4: (C) | M4: (D) | N4: (E) | O4: (F)=(D+E) | P4: (G) | Q4: (H) | R4: (I) | S4: (J)=(F/G)-1 | T4: (K)=(F/H)-1 | U4: (L)=(FX55%) | V4: (M) | W4: (N)=(F-M)
A5: 1 | B5: 北一區 | C5: 100 | D5: 營業部 | E5: =VLOOKUP(C5,'115_分行業績'!A:J,8,0) -> 151815331 | F5: =VLOOKUP(C5,'115_分行業績'!A:J,9,0) -> 103860000 | G5: =VLOOKUP(C5, '115_分行業績'!A:G,7,0) -> 1.4617305 | H5: =VLOOKUP(X5,原始參數_115!A:D,2,0) -> 130%以上，未達150% | I5: =VLOOKUP(X5,原始參數_115!A:D,4,0) -> 預估實績*90% | J5: =VLOOKUP(C5,'115_分行業績'!A:N,14,0) -> 136630000 | L5: =IF(J5 = M5, "-", M5) -> 2995449 | M5: =O5-N5 -> 2995449 | N5: =VLOOKUP(C5,'116目標底稿ver1'!D:AC, 19,0) -> 1154551 | O5: =VLOOKUP(C5,'116目標底稿ver1'!D:AC, 22, 0) -> 4150000 | P5: 78160000 | Q5: 96927210 | R5: =ROUND(Q5/P5, 2) -> 1.24 | S5: =O5/P5-1 -> -0.94690379 | T5: =O5/Q5-1 -> -0.95718437 | U5: =O5*0.55 -> 2282500 | V5: 103560000 | W5: =O5-V5 -> -99410000 | X5: =IF(G5>=2, "TYPE_1", IF(G5>=1.5, "TYPE_2", IF(G5>=1.3, "TYPE_3", IF(G5>=1.2, "TYPE_4", IF(G5 >=1.1, "TYPE_5", IF(G5>=1, "TYPE_6", IF(G5>=0.9, "TYPE_7", IF(G5>= 0.75, "TYPE_8", "TYPE_9")))))))) -> TYPE_3
A6: 2 | B6: 北一區 | C6: 101 | D6: 儲蓄分行 | E6: =VLOOKUP(C6,'115_分行業績'!A:J,8,0) -> 24773020 | F6: =VLOOKUP(C6,'115_分行業績'!A:J,9,0) -> 36030000 | G6: =VLOOKUP(C6, '115_分行業績'!A:G,7,0) -> 0.68756647 | H6: =VLOOKUP(X6,原始參數_115!A:D,2,0) -> 未達75% | I6: =VLOOKUP(X6,原始參數_115!A:D,4,0) -> 分行目標*115% | J6: =VLOOKUP(C6,'115_分行業績'!A:N,14,0) -> 41430000 | L6: =IF(J6 = M6, "-", M6) -> 1112724 | M6: =O6-N6 -> 1112724 | N6: =VLOOKUP(C6,'116目標底稿ver1'!D:AC, 19,0) -> 577276 | O6: =VLOOKUP(C6,'116目標底稿ver1'!D:AC, 22, 0) -> 1690000 | P6: 29230000 | Q6: 19689586 | R6: =ROUND(Q6/P6, 2) -> 0.67 | S6: =O6/P6-1 -> -0.94218269 | T6: =O6/Q6-1 -> -0.91416782 | U6: =O6*0.55 -> 929500 | V6: 35820000 | W6: =O6-V6 -> -34130000 | X6: =IF(G6>=2, "TYPE_1", IF(G6>=1.5, "TYPE_2", IF(G6>=1.3, "TYPE_3", IF(G6>=1.2, "TYPE_4", IF(G6 >=1.1, "TYPE_5", IF(G6>=1, "TYPE_6", IF(G6>=0.9, "TYPE_7", IF(G6>= 0.75, "TYPE_8", "TYPE_9")))))))) -> TYPE_9
A7: 3 | B7: 北一區 | C7: 103 | D7: 城內分行 | E7: =VLOOKUP(C7,'115_分行業績'!A:J,8,0) -> 43030534 | F7: =VLOOKUP(C7,'115_分行業績'!A:J,9,0) -> 44220000 | G7: =VLOOKUP(C7, '115_分行業績'!A:G,7,0) -> 0.97310118 | H7: =VLOOKUP(X7,原始參數_115!A:D,2,0) -> 90%以上，未達100% | I7: =VLOOKUP(X7,原始參數_115!A:D,4,0) -> 分行目標*105% | J7: =VLOOKUP(C7,'115_分行業績'!A:N,14,0) -> 46430000 | L7: =IF(J7 = M7, "-", M7) -> 1142630 | M7: =O7-N7 -> 1142630 | N7: =VLOOKUP(C7,'116目標底稿ver1'!D:AC, 19,0) -> 557370 | O7: =VLOOKUP(C7,'116目標底稿ver1'!D:AC, 22, 0) -> 1700000 | P7: 39690000 | Q7: 35669507 | R7: =ROUND(Q7/P7, 2) -> 0.9 | S7: =O7/P7-1 -> -0.95716805 | T7: =O7/Q7-1 -> -0.95234024 | U7: =O7*0.55 -> 935000 | V7: 44100000 | W7: =O7-V7 -> -42400000 | X7: =IF(G7>=2, "TYPE_1", IF(G7>=1.5, "TYPE_2", IF(G7>=1.3, "TYPE_3", IF(G7>=1.2, "TYPE_4", IF(G7 >=1.1, "TYPE_5", IF(G7>=1, "TYPE_6", IF(G7>=0.9, "TYPE_7", IF(G7>= 0.75, "TYPE_8", "TYPE_9")))))))) -> TYPE_7
A8: 4 | B8: 北一區 | C8: 104 | D8: 大稻埕分行 | E8: =VLOOKUP(C8,'115_分行業績'!A:J,8,0) -> 100530724 | F8: =VLOOKUP(C8,'115_分行業績'!A:J,9,0) -> 75640000 | G8: =VLOOKUP(C8, '115_分行業績'!A:G,7,0) -> 1.3290683 | H8: =VLOOKUP(X8,原始參數_115!A:D,2,0) -> 130%以上，未達150% | I8: =VLOOKUP(X8,原始參數_115!A:D,4,0) -> 預估實績*90% | J8: =VLOOKUP(C8,'115_分行業績'!A:N,14,0) -> 90480000 | L8: =IF(J8 = M8, "-", M8) -> 2222818 | M8: =O8-N8 -> 2222818 | N8: =VLOOKUP(C8,'116目標底稿ver1'!D:AC, 19,0) -> 597182 | O8: =VLOOKUP(C8,'116目標底稿ver1'!D:AC, 22, 0) -> 2820000 | P8: 64940000 | Q8: 54762070 | R8: =ROUND(Q8/P8, 2) -> 0.84 | S8: =O8/P8-1 -> -0.9565753 | T8: =O8/Q8-1 -> -0.9485045 | U8: =O8*0.55 -> 1551000 | V8: 75400000 | W8: =O8-V8 -> -72580000 | X8: =IF(G8>=2, "TYPE_1", IF(G8>=1.5, "TYPE_2", IF(G8>=1.3, "TYPE_3", IF(G8>=1.2, "TYPE_4", IF(G8 >=1.1, "TYPE_5", IF(G8>=1, "TYPE_6", IF(G8>=0.9, "TYPE_7", IF(G8>= 0.75, "TYPE_8", "TYPE_9")))))))) -> TYPE_3
A9: 5 | B9: 北一區 | C9: 105 | D9: 建成分行 | E9: =VLOOKUP(C9,'115_分行業績'!A:J,8,0) -> 29760269 | F9: =VLOOKUP(C9,'115_分行業績'!A:J,9,0) -> 57000000 | G9: =VLOOKUP(C9, '115_分行業績'!A:G,7,0) -> 0.52210998 | H9: =VLOOKUP(X9,原始參數_115!A:D,2,0) -> 未達75% | I9: =VLOOKUP(X9,原始參數_115!A:D,4,0) -> 分行目標*115% | J9: =VLOOKUP(C9,'115_分行業績'!A:N,14,0) -> 65550000 | L9: =IF(J9 = M9, "-", M9) -> 1633382 | M9: =O9-N9 -> 1633382 | N9: =VLOOKUP(C9,'116目標底稿ver1'!D:AC, 19,0) -> 716618 | O9: =VLOOKUP(C9,'116目標底稿ver1'!D:AC, 22, 0) -> 2350000 | P9: 48860000 | Q9: 38310005 | R9: =ROUND(Q9/P9, 2) -> 0.78 | S9: =O9/P9-1 -> -0.9519034 | T9: =O9/Q9-1 -> -0.93865832 | U9: =O9*0.55 -> 1292500 | V9: 56980000 | W9: =O9-V9 -> -54630000 | X9: =IF(G9>=2, "TYPE_1", IF(G9>=1.5, "TYPE_2", IF(G9>=1.3, "TYPE_3", IF(G9>=1.2, "TYPE_4", IF(G9 >=1.1, "TYPE_5", IF(G9>=1, "TYPE_6", IF(G9>=0.9, "TYPE_7", IF(G9>= 0.75, "TYPE_8", "TYPE_9")))))))) -> TYPE_9
A10: 6 | B10: 北一區 | C10: 106 | D10: 中山分行 | E10: =VLOOKUP(C10,'115_分行業績'!A:J,8,0) -> 91410089 | F10: =VLOOKUP(C10,'115_分行業績'!A:J,9,0) -> 99340000 | G10: =VLOOKUP(C10, '115_分行業績'!A:G,7,0) -> 0.92017404 | H10: =VLOOKUP(X10,原始參數_115!A:D,2,0) -> 90%以上，未達100% | I10: =VLOOKUP(X10,原始參數_115!A:D,4,0) -> 分行目標*105% | J10: =VLOOKUP(C10,'115_分行業績'!A:N,14,0) -> 104310000 | L10: =IF(J10 = M10, "-", M10) -> 2703946 | M10: =O10-N10 -> 2703946 | N10: =VLOOKUP(C10,'116目標底稿ver1'!D:AC, 19,0) -> 836054 | O10: =VLOOKUP(C10,'116目標底稿ver1'!D:AC, 22, 0) -> 3540000 | P10: 85510000 | Q10: 66866945 | R10: =ROUND(Q10/P10, 2) -> 0.78 | S10: =O10/P10-1 -> -0.95860133 | T10: =O10/Q10-1 -> -0.94705904 | U10: =O10*0.55 -> 1947000 | V10: 99040000 | W10: =O10-V10 -> -95500000 | X10: =IF(G10>=2, "TYPE_1", IF(G10>=1.5, "TYPE_2", IF(G10>=1.3, "TYPE_3", IF(G10>=1.2, "TYPE_4", IF(G10 >=1.1, "TYPE_5", IF(G10>=1, "TYPE_6", IF(G10>=0.9, "TYPE_7", IF(G10>= 0.75, "TYPE_8", "TYPE_9")))))))) -> TYPE_7
A11: 7 | B11: 北一區 | C11: 107 | D11: 圓山分行 | E11: =VLOOKUP(C11,'115_分行業績'!A:J,8,0) -> 142594489 | F11: =VLOOKUP(C11,'115_分行業績'!A:J,9,0) -> 118090000 | G11: =VLOOKUP(C11, '115_分行業績'!A:G,7,0) -> 1.2075069 | H11: =VLOOKUP(X11,原始參數_115!A:D,2,0) -> 120%以上，未達130% | I11: =VLOOKUP(X11,原始參數_115!A:D,4,0) -> 預估實績*101% | J11: =VLOOKUP(C11,'115_分行業績'!A:N,14,0) -> 144020000 | L11: =IF(J11 = M11, "-", M11) -> 3544979 | M11: =O11-N11 -> 3544979 | N11: =VLOOKUP(C11,'116目標底稿ver1'!D:AC, 19,0) -> 1055021 | O11: =VLOOKUP(C11,'116目標底稿ver1'!D:AC, 22, 0) -> 4600000 | P11: 105180000 | Q11: 106107606 | R11: =ROUND(Q11/P11, 2) -> 1.01 | S11: =O11/P11-1 -> -0.95626545 | T11: =O11/Q11-1 -> -0.95664778 | U11: =O11*0.55 -> 2530000 | V11: 117790000 | W11: =O11-V11 -> -113190000 | X11: =IF(G11>=2, "TYPE_1", IF(G11>=1.5, "TYPE_2", IF(G11>=1.3, "TYPE_3", IF(G11>=1.2, "TYPE_4", IF(G11 >=1.1, "TYPE_5", IF(G11>=1, "TYPE_6", IF(G11>=0.9, "TYPE_7", IF(G11>= 0.75, "TYPE_8", "TYPE_9")))))))) -> TYPE_4
A12: 8 | B12: 北一區 | C12: 108 | D12: 城東分行 | E12: =VLOOKUP(C12,'115_分行業績'!A:J,8,0) -> 181181359 | F12: =VLOOKUP(C12,'115_分行業績'!A:J,9,0) -> 129150000 | G12: =VLOOKUP(C12, '115_分行業績'!A:G,7,0) -> 1.4028754 | H12: =VLOOKUP(X12,原始參數_115!A:D,2,0) -> 130%以上，未達150% | I12: =VLOOKUP(X12,原始參數_115!A:D,4,0) -> 預估實績*90% | J12: =VLOOKUP(C12,'115_分行業績'!A:N,14,0) -> 163060000 | L12: =IF(J12 = M12, "-", M12) -> 2916858 | M12: =O12-N12 -> 2916858 | N12: =VLOOKUP(C12,'116目標底稿ver1'!D:AC, 19,0) -> 1453142 | O12: =VLOOKUP(C12,'116目標底稿ver1'!D:AC, 22, 0) -> 4370000 | P12: 115000000 | Q12: 80802504 | R12: =ROUND(Q12/P12, 2) -> 0.7 | S12: =O12/P12-1 -> -0.962 | T12: =O12/Q12-1 -> -0.94591752 | U12: =O12*0.55 -> 2403500 | V12: 126000000 | W12: =O12-V12 -> -121630000 | X12: =IF(G12>=2, "TYPE_1", IF(G12>=1.5, "TYPE_2", IF(G12>=1.3, "TYPE_3", IF(G12>=1.2, "TYPE_4", IF(G12 >=1.1, "TYPE_5", IF(G12>=1, "TYPE_6", IF(G12>=0.9, "TYPE_7", IF(G12>= 0.75, "TYPE_8", "TYPE_9")))))))) -> TYPE_3
A13: 9 | B13: 北一區 | C13: 109 | D13: 西門分行 | E13: =VLOOKUP(C13,'115_分行業績'!A:J,8,0) -> 29449723 | F13: =VLOOKUP(C13,'115_分行業績'!A:J,9,0) -> 37980000 | G13: =VLOOKUP(C13, '115_分行業績'!A:G,7,0) -> 0.77540082 | H13: =VLOOKUP(X13,原始參數_115!A:D,2,0) -> 75%以上，未達90% | I13: =VLOOKUP(X13,原始參數_115!A:D,4,0) -> 分行目標*110% | J13: =VLOOKUP(C13,'115_分行業績'!A:N,14,0) -> 41780000 | L13: =IF(J13 = M13, "-", M13) -> 1073006 | M13: =O13-N13 -> 1073006 | N13: =VLOOKUP(C13,'116目標底稿ver1'!D:AC, 19,0) -> 636994 | O13: =VLOOKUP(C13,'116目標底稿ver1'!D:AC, 22, 0) -> 1710000 | P13: 30930000 | Q13: 17150369 | R13: =ROUND(Q13/P13, 2) -> 0.55 | S13: =O13/P13-1 -> -0.94471387 | T13: =O13/Q13-1 -> -0.90029369 | U13: =O13*0.55 -> 940500 | V13: 37860000 | W13: =O13-V13 -> -36150000 | X13: =IF(G13>=2, "TYPE_1", IF(G13>=1.5, "TYPE_2", IF(G13>=1.3, "TYPE_3", IF(G13>=1.2, "TYPE_4", IF(G13 >=1.1, "TYPE_5", IF(G13>=1, "TYPE_6", IF(G13>=0.9, "TYPE_7", IF(G13>= 0.75, "TYPE_8", "TYPE_9")))))))) -> TYPE_8
A14: 10 | B14: 北一區 | C14: 110 | D14: 南松山分行 | E14: =VLOOKUP(C14,'115_分行業績'!A:J,8,0) -> 44041600 | F14: =VLOOKUP(C14,'115_分行業績'!A:J,9,0) -> 59470000 | G14: =VLOOKUP(C14, '115_分行業績'!A:G,7,0) -> 0.74056836 | H14: =VLOOKUP(X14,原始參數_115!A:D,2,0) -> 未達75% | I14: =VLOOKUP(X14,原始參數_115!A:D,4,0) -> 分行目標*115% | J14: =VLOOKUP(C14,'115_分行業績'!A:N,14,0) -> 68390000 | L14: =IF(J14 = M14, "-", M14) -> 1522818 | M14: =O14-N14 -> 1522818 | N14: =VLOOKUP(C14,'116目標底稿ver1'!D:AC, 19,0) -> 597182 | O14: =VLOOKUP(C14,'116目標底稿ver1'!D:AC, 22, 0) -> 2120000 | P14: 51170000 | Q14: 39462213 | R14: =ROUND(Q14/P14, 2) -> 0.77 | S14: =O14/P14-1 -> -0.95856947 | T14: =O14/Q14-1 -> -0.94627772 | U14: =O14*0.55 -> 1166000 | V14: 59320000 | W14: =O14-V14 -> -57200000 | X14: =IF(G14>=2, "TYPE_1", IF(G14>=1.5, "TYPE_2", IF(G14>=1.3, "TYPE_3", IF(G14>=1.2, "TYPE_4", IF(G14 >=1.1, "TYPE_5", IF(G14>=1, "TYPE_6", IF(G14>=0.9, "TYPE_7", IF(G14>= 0.75, "TYPE_8", "TYPE_9")))))))) -> TYPE_9
A15: 11 | B15: 北一區 | C15: 111 | D15: 仁愛路分行 | E15: =VLOOKUP(C15,'115_分行業績'!A:J,8,0) -> 156079156 | F15: =VLOOKUP(C15,'115_分行業績'!A:J,9,0) -> 101770000 | G15: =VLOOKUP(C15, '115_分行業績'!A:G,7,0) -> 1.533646 | H15: =VLOOKUP(X15,原始參數_115!A:D,2,0) -> 150%以上，未達200% | I15: =VLOOKUP(X15,原始參數_115!A:D,4,0) -> 預估實績*80% | J15: =VLOOKUP(C15,'115_分行業績'!A:N,14,0) -> 124860000 | L15: =IF(J15 = M15, "-", M15) -> 2763852 | M15: =O15-N15 -> 2763852 | N15: =VLOOKUP(C15,'116目標底稿ver1'!D:AC, 19,0) -> 816148 | O15: =VLOOKUP(C15,'116目標底稿ver1'!D:AC, 22, 0) -> 3580000 | P15: 87800000 | Q15: 60233303 | R15: =ROUND(Q15/P15, 2) -> 0.69 | S15: =O15/P15-1 -> -0.95922551 | T15: =O15/Q15-1 -> -0.94056444 | U15: =O15*0.55 -> 1969000 | V15: 101590000 | W15: =O15-V15 -> -98010000 | X15: =IF(G15>=2, "TYPE_1", IF(G15>=1.5, "TYPE_2", IF(G15>=1.3, "TYPE_3", IF(G15>=1.2, "TYPE_4", IF(G15 >=1.1, "TYPE_5", IF(G15>=1, "TYPE_6", IF(G15>=0.9, "TYPE_7", IF(G15>= 0.75, "TYPE_8", "TYPE_9")))))))) -> TYPE_2
A16: 12 | B16: 北一區 | C16: 112 | D16: 南京東路分行 | E16: =VLOOKUP(C16,'115_分行業績'!A:J,8,0) -> 81157545 | F16: =VLOOKUP(C16,'115_分行業績'!A:J,9,0) -> 68030000 | G16: =VLOOKUP(C16, '115_分行業績'!A:G,7,0) -> 1.192967 | H16: =VLOOKUP(X16,原始參數_115!A:D,2,0) -> 110%以上，未達120% | I16: =VLOOKUP(X16,原始參數_115!A:D,4,0) -> 預估實績*103% | J16: =VLOOKUP(C16,'115_分行業績'!A:N,14,0) -> 83590000 | L16: =IF(J16 = M16, "-", M16) -> 2424791 | M16: =O16-N16 -> 2424791 | N16: =VLOOKUP(C16,'116目標底稿ver1'!D:AC, 19,0) -> 1015209 | O16: =VLOOKUP(C16,'116目標底稿ver1'!D:AC, 22, 0) -> 3440000 | P16: 57240000 | Q16: 43209787 | R16: =ROUND(Q16/P16, 2) -> 0.75 | S16: =O16/P16-1 -> -0.93990217 | T16: =O16/Q16-1 -> -0.92038841 | U16: =O16*0.55 -> 1892000 | V16: 67730000 | W16: =O16-V16 -> -64290000 | X16: =IF(G16>=2, "TYPE_1", IF(G16>=1.5, "TYPE_2", IF(G16>=1.3, "TYPE_3", IF(G16>=1.2, "TYPE_4", IF(G16 >=1.1, "TYPE_5", IF(G16>=1, "TYPE_6", IF(G16>=0.9, "TYPE_7", IF(G16>= 0.75, "TYPE_8", "TYPE_9")))))))) -> TYPE_5
... A187: 183 | B187: 北一區 | C187: 888 | D187: 營運總部分行 | E187: =VLOOKUP(C187,'115_分行業績'!A:J,8,0) -> 23269991 | F187: =VLOOKUP(C187,'115_分行業績'!A:J,9,0) -> 17160000 | G187: =VLOOKUP(C187, '115_分行業績'!A:G,7,0) -> 1.3560601 | H187: =VLOOKUP(X187,原始參數_115!A:D,2,0) -> 130%以上，未達150% | I187: =VLOOKUP(X187,原始參數_115!A:D,4,0) -> 預估實績*90% | J187: =VLOOKUP(C187,'115_分行業績'!A:N,14,0) -> 20940000 | L187: =IF(J187 = M187, "-", M187) -> 622067 | M187: =O187-N187 -> 622067 | N187: =VLOOKUP(C187,'116目標底稿ver1'!D:AC, 19,0) -> 437933 | O187: =VLOOKUP(C187,'116目標底稿ver1'!D:AC, 22, 0) -> 1060000 | P187: 14290000 | Q187: 11645179 | R187: =ROUND(Q187/P187, 2) -> 0.81 | S187: =O187/P187-1 -> -0.92582225 | T187: =O187/Q187-1 -> -0.90897521 | U187: =O187*0.55 -> 583000 | V187: 17130000 | W187: =O187-V187 -> -16070000 | X187: =IF(G187>=2, "TYPE_1", IF(G187>=1.5, "TYPE_2", IF(G187>=1.3, "TYPE_3", IF(G187>=1.2, "TYPE_4", IF(G187 >=1.1, "TYPE_5", IF(G187>=1, "TYPE_6", IF(G187>=0.9, "TYPE_7", IF(G187>= 0.75, "TYPE_8", "TYPE_9")))))))) -> TYPE_3
A188: 總計 | E188: =SUM(E5:E187) -> 12485599369 | F188: =SUM(F5:F187) -> 11785380000 | G188: ='115_分行業績'!G1 -> 1.0593381 | H188: - | I188: - | J188: =SUM(J5:J187) -> 13610270000 | L188: =SUM(#REF!) -> #REF! | M188: =SUM(#REF!) -> #REF! | N188: =SUM(#REF!) -> #REF! | O188: =SUM(#REF!) -> #REF! | P188: =SUM(#REF!) -> #REF! | Q188: =SUM(#REF!) -> #REF! | R188: =ROUND(Q188/P188, 2) -> #REF! | S188: =O188/P188-1 -> #REF! | T188: =O188/Q188-1 -> #REF! | U188: =SUM(#REF!) -> #REF! | V188: 11800000000

Sheet 財管手收表
A1: 115年度營業單位財富管理業務手續費收入目標表
D2: 單位:新臺幣元
A3: 通路中心 | B3: 單位代號 | C3: 單位名稱 | D3: 財富管理 手續費收入目標 | E3: 財富管理手續費收入對盈餘目標之影響數 | H3: 列標籤 | I3: 計數 - 單位代號
A4: 北一區 | B4: 100 | C4: 營業部 | D4: =VLOOKUP(B4,'116目標底稿ver1'!D:AC, 22,0) -> 4150000 | E4: =VLOOKUP(B4,全年KPI!B:J, 9,0) -> 99769000 | H4: 北一區 | I4: 46
A5: 北一區 | B5: 101 | C5: 儲蓄分行 | D5: =VLOOKUP(B5,'116目標底稿ver1'!D:AC, 22,0) -> 1690000 | E5: =VLOOKUP(B5,全年KPI!B:J, 9,0) -> 34522000 | H5: 北二區 | I5: 36
A6: 北一區 | B6: 103 | C6: 城內分行 | D6: =VLOOKUP(B6,'116目標底稿ver1'!D:AC, 22,0) -> 1700000 | E6: =VLOOKUP(B6,全年KPI!B:J, 9,0) -> 42487000 | H6: 北三區 | I6: 33
A7: 北一區 | B7: 104 | C7: 大稻埕分行 | D7: =VLOOKUP(B7,'116目標底稿ver1'!D:AC, 22,0) -> 2820000 | E7: =VLOOKUP(B7,全年KPI!B:J, 9,0) -> 72627000 | H7: 中區 | I7: 31
A8: 北一區 | B8: 105 | C8: 建成分行 | D8: =VLOOKUP(B8,'116目標底稿ver1'!D:AC, 22,0) -> 2350000 | E8: =VLOOKUP(B8,全年KPI!B:J, 9,0) -> 54900000 | H8: 南區 | I8: 39
A9: 北一區 | B9: 106 | C9: 中山分行 | D9: =VLOOKUP(B9,'116目標底稿ver1'!D:AC, 22,0) -> 3540000 | E9: =VLOOKUP(B9,全年KPI!B:J, 9,0) -> 95388000 | H9: 總計 | I9: 185
A10: 北一區 | B10: 107 | C10: 圓山分行 | D10: =VLOOKUP(B10,'116目標底稿ver1'!D:AC, 22,0) -> 4600000 | E10: =VLOOKUP(B10,全年KPI!B:J, 9,0) -> 113470000
A11: 北一區 | B11: 108 | C11: 城東分行 | D11: =VLOOKUP(B11,'116目標底稿ver1'!D:AC, 22,0) -> 4370000 | E11: =VLOOKUP(B11,全年KPI!B:J, 9,0) -> 122982000
A12: 北一區 | B12: 109 | C12: 西門分行 | D12: =VLOOKUP(B12,'116目標底稿ver1'!D:AC, 22,0) -> 1710000 | E12: =VLOOKUP(B12,全年KPI!B:J, 9,0) -> 36491000
A13: 北一區 | B13: 110 | C13: 南松山分行 | D13: =VLOOKUP(B13,'116目標底稿ver1'!D:AC, 22,0) -> 2120000 | E13: =VLOOKUP(B13,全年KPI!B:J, 9,0) -> 57148000
A14: 北一區 | B14: 111 | C14: 仁愛路分行 | D14: =VLOOKUP(B14,'116目標底稿ver1'!D:AC, 22,0) -> 3580000 | E14: =VLOOKUP(B14,全年KPI!B:J, 9,0) -> 97848000
A15: 北一區 | B15: 112 | C15: 南京東路分行 | D15: =VLOOKUP(B15,'116目標底稿ver1'!D:AC, 22,0) -> 3440000 | E15: =VLOOKUP(B15,全年KPI!B:J, 9,0) -> 65306000
A16: 北一區 | B16: 113 | C16: 新生分行 | D16: =VLOOKUP(B16,'116目標底稿ver1'!D:AC, 22,0) -> 3130000 | E16: =VLOOKUP(B16,全年KPI!B:J, 9,0) -> 87721000
A17: 北一區 | B17: 114 | C17: 大同分行 | D17: =VLOOKUP(B17,'116目標底稿ver1'!D:AC, 22,0) -> 2980000 | E17: =VLOOKUP(B17,全年KPI!B:J, 9,0) -> 80112000
A18: 北一區 | B18: 115 | C18: 松山分行 | D18: =VLOOKUP(B18,'116目標底稿ver1'!D:AC, 22,0) -> 2100000 | E18: =VLOOKUP(B18,全年KPI!B:J, 9,0) -> 69139000
A19: 北一區 | B19: 116 | C19: 中崙分行 | D19: =VLOOKUP(B19,'116目標底稿ver1'!D:AC, 22,0) -> 2080000 | E19: =VLOOKUP(B19,全年KPI!B:J, 9,0) -> 48107000
A20: 北一區 | B20: 117 | C20: 台北南門分行 | D20: =VLOOKUP(B20,'116目標底稿ver1'!D:AC, 22,0) -> 2900000 | E20: =VLOOKUP(B20,全年KPI!B:J, 9,0) -> 73078000
A21: 北一區 | B21: 118 | C21: 公館分行 | D21: =VLOOKUP(B21,'116目標底稿ver1'!D:AC, 22,0) -> 2570000 | E21: =VLOOKUP(B21,全年KPI!B:J, 9,0) -> 70773000
... A188: 北一區 | B188: 888 | C188: 營運總部分行 | D188: =VLOOKUP(B188,'116目標底稿ver1'!D:AC, 22,0) -> 1060000 | E188: =VLOOKUP(B188,全年KPI!B:J, 9,0) -> 16526000
A189: 北一區 | C189: 合計 | D189: =SUMIF($A$4:$A$188,A189,$D$4:$D$188) -> 113390000 | E189: =SUMIF($A$4:$A$188,A189,$E$4:$E$188) -> 2857400000
A190: 北二區 | C190: 合計 | D190: =SUMIF($A$4:$A$188,A190,$D$4:$D$188) -> 87520000 | E190: =SUMIF($A$4:$A$188,A190,$E$4:$E$188) -> 2333907000
A191: 北三區 | C191: 合計 | D191: =SUMIF($A$4:$A$188,A191,$D$4:$D$188) -> 71300000 | E191: =SUMIF($A$4:$A$188,A191,$E$4:$E$188) -> 1843493000
A192: 中區 | C192: 合計 | D192: =SUMIF($A$4:$A$188,A192,$D$4:$D$188) -> 79180000 | E192: =SUMIF($A$4:$A$188,A192,$E$4:$E$188) -> 2110329000
A193: 南區 | C193: 合計 | D193: =SUMIF($A$4:$A$188,A193,$D$4:$D$188) -> #N/A | E193: =SUMIF($A$4:$A$188,A193,$E$4:$E$188) -> 2192308000
A194: 總 計 | D194: =SUM(D189:D193) -> #N/A | E194: =SUM(E189:E193) -> 11337437000

Sheet 客群經營目標表
A1: 115年度營業單位客群經營目標表
D2: 單位:新臺幣元
A3: 通路中心 | B3: 單位代號 | C3: 單位名稱 | D3: 客群經營目標 | G3: 列標籤 | H3: 計數 - 單位代號
A4: 北一區 | B4: 100 | C4: 營業部 | D4: =VLOOKUP(B4,'116目標底稿ver1'!D:AC, 26,0) -> 71516500 | G4: 北一區 | H4: 46
A5: 北一區 | B5: 101 | C5: 儲蓄分行 | D5: =VLOOKUP(B5,'116目標底稿ver1'!D:AC, 26,0) -> 19954000 | G5: 北二區 | H5: 36
A6: 北一區 | B6: 103 | C6: 城內分行 | D6: =VLOOKUP(B6,'116目標底稿ver1'!D:AC, 26,0) -> 25311000 | G6: 北三區 | H6: 33
A7: 北一區 | B7: 104 | C7: 大稻埕分行 | D7: =VLOOKUP(B7,'116目標底稿ver1'!D:AC, 26,0) -> 51975000 | G7: 中區 | H7: 31
A8: 北一區 | B8: 105 | C8: 建成分行 | D8: =VLOOKUP(B8,'116目標底稿ver1'!D:AC, 26,0) -> 31388500 | G8: 南區 | H8: 39
A9: 北一區 | B9: 106 | C9: 中山分行 | D9: =VLOOKUP(B9,'116目標底稿ver1'!D:AC, 26,0) -> 53729500 | G9: 總計 | H9: 185
A10: 北一區 | B10: 107 | C10: 圓山分行 | D10: =VLOOKUP(B10,'116目標底稿ver1'!D:AC, 26,0) -> 81251500
A11: 北一區 | B11: 108 | C11: 城東分行 | D11: =VLOOKUP(B11,'116目標底稿ver1'!D:AC, 26,0) -> 88495000
A12: 北一區 | B12: 109 | C12: 西門分行 | D12: =VLOOKUP(B12,'116目標底稿ver1'!D:AC, 26,0) -> 20993500
A13: 北一區 | B13: 110 | C13: 南松山分行 | D13: =VLOOKUP(B13,'116目標底稿ver1'!D:AC, 26,0) -> 32565500
A14: 北一區 | B14: 111 | C14: 仁愛路分行 | D14: =VLOOKUP(B14,'116目標底稿ver1'!D:AC, 26,0) -> 69811500
A15: 北一區 | B15: 112 | C15: 南京東路分行 | D15: =VLOOKUP(B15,'116目標底稿ver1'!D:AC, 26,0) -> 46975500
A16: 北一區 | B16: 113 | C16: 新生分行 | D16: =VLOOKUP(B16,'116目標底稿ver1'!D:AC, 26,0) -> 56452000
A17: 北一區 | B17: 114 | C17: 大同分行 | D17: =VLOOKUP(B17,'116目標底稿ver1'!D:AC, 26,0) -> 45694000
A18: 北一區 | B18: 115 | C18: 松山分行 | D18: =VLOOKUP(B18,'116目標底稿ver1'!D:AC, 26,0) -> 30162000
A19: 北一區 | B19: 116 | C19: 中崙分行 | D19: =VLOOKUP(B19,'116目標底稿ver1'!D:AC, 26,0) -> 27593500
A20: 北一區 | B20: 117 | C20: 台北南門分行 | D20: =VLOOKUP(B20,'116目標底稿ver1'!D:AC, 26,0) -> 48455000
A21: 北一區 | B21: 118 | C21: 公館分行 | D21: =VLOOKUP(B21,'116目標底稿ver1'!D:AC, 26,0) -> 39374500
... A188: 北一區 | B188: 888 | C188: 營運總部分行 | D188: =VLOOKUP(B188,'116目標底稿ver1'!D:AC, 26,0) -> 12023000
A189: 北一區 | C189: 合計 | D189: =SUMIF($A$4:$A$188,A189,$D$4:$D$188) -> 1799941000
A190: 北二區 | C190: 合計 | D190: =SUMIF($A$4:$A$188,A190,$D$4:$D$188) -> 1512021500
A191: 北三區 | C191: 合計 | D191: =SUMIF($A$4:$A$188,A191,$D$4:$D$188) -> 1154989000
A192: 中區 | C192: 合計 | D192: =SUMIF($A$4:$A$188,A192,$D$4:$D$188) -> 1311871000
A193: 南區 | C193: 合計 | D193: =SUMIF($A$4:$A$188,A193,$D$4:$D$188) -> #N/A
A194: 總 計 | D194: =SUM(D189:D193) -> #N/A

Sheet 財管手收各月
B1: 1 | C1: 2 | D1: 3 | E1: 4 | F1: 5 | G1: 6 | H1: 7 | I1: 8 | J1: 9 | K1: 10 | L1: 11 | M1: 12 | N1: 13 | O1: 14 | P1: 15
A2: 115年度各月營業單位財富管理業務手續費收入目標表
P3: 單位：新臺幣元
A4: 通路中心 | B4: 單位 代號 | C4: 單位 名稱 | D4: 1月 | E4: 2月 | F4: 3月 | G4: 4月 | H4: 5月 | I4: 6月 | J4: 7月 | K4: 8月 | L4: 9月 | M4: 10月 | N4: 11月 | O4: 12月 | P4: 合計
D5: (A) | E5: (B) | F5: (C) | G5: (D) | H5: (E) | I5: (F) | J5: (G) | K5: (H) | L5: (I) | M5: (J) | N5: (K) | O5: (L) | P5: (M) = SUM(A:L)
A6: 北一區 | B6: 100 | C6: 營業部 | D6: 11439000 | E6: 8800000 | F6: 8800000 | G6: 8361000 | H6: 9681000 | I6: 8361000 | J6: 8361000 | K6: 9681000 | L6: 8361000 | M6: 8800000 | N6: 9681000 | O6: 3514000 | P6: =SUM(D6:O6) -> 103840000
A7: 北一區 | B7: 101 | C7: 儲蓄分行 | D7: 3959000 | E7: 3045000 | F7: 3045000 | G7: 2892000 | H7: 3349000 | I7: 2892000 | J7: 2892000 | K7: 3349000 | L7: 2892000 | M7: 3045000 | N7: 3349000 | O7: 1221000 | P7: =SUM(D7:O7) -> 35930000
A8: 北一區 | B8: 103 | C8: 城內分行 | D8: 4872000 | E8: 3748000 | F8: 3748000 | G8: 3560000 | H8: 4122000 | I8: 3560000 | J8: 3560000 | K8: 4122000 | L8: 3560000 | M8: 3748000 | N8: 4122000 | O8: 1498000 | P8: =SUM(D8:O8) -> 44220000
A9: 北一區 | B9: 104 | C9: 大稻埕分行 | D9: 8328000 | E9: 6406000 | F9: 6406000 | G9: 6086000 | H9: 7047000 | I9: 6086000 | J9: 6086000 | K9: 7047000 | L9: 6086000 | M9: 6406000 | N9: 7047000 | O9: 2559000 | P9: =SUM(D9:O9) -> 75590000
A10: 北一區 | B10: 105 | C10: 建成分行 | D10: 6295000 | E10: 4843000 | F10: 4843000 | G10: 4601000 | H10: 5326000 | I10: 4601000 | J10: 4601000 | K10: 5326000 | L10: 4601000 | M10: 4843000 | N10: 5326000 | O10: 1934000 | P10: =SUM(D10:O10) -> 57140000
A11: 北一區 | B11: 106 | C11: 中山分行 | D11: 10937000 | E11: 8413000 | F11: 8413000 | G11: 7994000 | H11: 9255000 | I11: 7994000 | J11: 7994000 | K11: 9255000 | L11: 7994000 | M11: 8413000 | N11: 9255000 | O11: 3363000 | P11: =SUM(D11:O11) -> 99280000
A12: 北一區 | B12: 107 | C12: 圓山分行 | D12: 13011000 | E12: 10009000 | F12: 10009000 | G12: 9508000 | H12: 11009000 | I12: 9508000 | J12: 9508000 | K12: 11009000 | L12: 9508000 | M12: 10009000 | N12: 11009000 | O12: 4003000 | P12: =SUM(D12:O12) -> 118100000
A13: 北一區 | B13: 108 | C13: 城東分行 | D13: 14101000 | E13: 10847000 | F13: 10847000 | G13: 10305000 | H13: 11932000 | I13: 10305000 | J13: 10305000 | K13: 11932000 | L13: 10305000 | M13: 10847000 | N13: 11932000 | O13: 4342000 | P13: =SUM(D13:O13) -> 128000000
A14: 北一區 | B14: 109 | C14: 西門分行 | D14: 4184000 | E14: 3219000 | F14: 3219000 | G14: 3058000 | H14: 3540000 | I14: 3058000 | J14: 3058000 | K14: 3540000 | L14: 3058000 | M14: 3219000 | N14: 3540000 | O14: 1287000 | P14: =SUM(D14:O14) -> 37980000
A15: 北一區 | B15: 110 | C15: 南松山分行 | D15: 6553000 | E15: 5040000 | F15: 5040000 | G15: 4789000 | H15: 5545000 | I15: 4789000 | J15: 4789000 | K15: 5545000 | L15: 4789000 | M15: 5040000 | N15: 5545000 | O15: 2016000 | P15: =SUM(D15:O15) -> 59480000
A16: 北一區 | B16: 111 | C16: 仁愛路分行 | D16: 11219000 | E16: 8631000 | F16: 8631000 | G16: 8199000 | H16: 9494000 | I16: 8199000 | J16: 8199000 | K16: 9494000 | L16: 8199000 | M16: 8631000 | N16: 9494000 | O16: 3450000 | P16: =SUM(D16:O16) -> 101840000
A17: 北一區 | B17: 112 | C17: 南京東路分行 | D17: 7489000 | E17: 5759000 | F17: 5759000 | G17: 5472000 | H17: 6335000 | I17: 5472000 | J17: 5472000 | K17: 6335000 | L17: 5472000 | M17: 5759000 | N17: 6335000 | O17: 2311000 | P17: =SUM(D17:O17) -> 67970000
... A190: 北一區 | B190: 888 | C190: 營運總部分行 | D190: 1895000 | E190: 1457000 | F190: 1457000 | G190: 1385000 | H190: 1604000 | I190: 1385000 | J190: 1385000 | K190: 1604000 | L190: 1385000 | M190: 1457000 | N190: 1604000 | O190: 582000 | P190: =SUM(D190:O190) -> 17200000
A191: 北一區 | C191: 合計 | D191: =SUMIF($A$6:$A$190,$A191,$D$6:$D$190) -> 327641000 | E191: =SUMIF($A$6:$A$190,$A191,$E$6:$E$190) -> 252026000 | F191: =SUMIF($A$6:$A$190,$A191,$F$6:$F$190) -> 252026000 | G191: =SUMIF($A$6:$A$190,$A191,$G$6:$G$190) -> 239435000 | H191: =SUMIF($A$6:$A$190,$A191,$H$6:$H$190) -> 277234000 | I191: =SUMIF($A$6:$A$190,$A191,$I$6:$I$190) -> 239435000 | J191: =SUMIF($A$6:$A$190,$A191,$J$6:$J$190) -> 239435000 | K191: =SUMIF($A$6:$A$190,$A191,$K$6:$K$190) -> 277234000 | L191: =SUMIF($A$6:$A$190,$A191,$L$6:$L$190) -> 239435000 | M191: =SUMIF($A$6:$A$190,$A191,$M$6:$M$190) -> 252026000 | N191: =SUMIF($A$6:$A$190,$A191,$N$6:$N$190) -> 277234000 | O191: =SUMIF($A$6:$A$190,$A191,$O$6:$O$190) -> 100819000 | P191: =SUM(D191:O191) -> 2973980000
A192: 北二區 | C192: 合計 | D192: =SUMIF($A$6:$A$190,$A192,$D$6:$D$190) -> 267610000 | E192: =SUMIF($A$6:$A$190,$A192,$E$6:$E$190) -> 205858000 | F192: =SUMIF($A$6:$A$190,$A192,$F$6:$F$190) -> 205858000 | G192: =SUMIF($A$6:$A$190,$A192,$G$6:$G$190) -> 195561000 | H192: =SUMIF($A$6:$A$190,$A192,$H$6:$H$190) -> 226451000 | I192: =SUMIF($A$6:$A$190,$A192,$I$6:$I$190) -> 195561000 | J192: =SUMIF($A$6:$A$190,$A192,$J$6:$J$190) -> 195561000 | K192: =SUMIF($A$6:$A$190,$A192,$K$6:$K$190) -> 226451000 | L192: =SUMIF($A$6:$A$190,$A192,$L$6:$L$190) -> 195561000 | M192: =SUMIF($A$6:$A$190,$A192,$M$6:$M$190) -> 205858000 | N192: =SUMIF($A$6:$A$190,$A192,$N$6:$N$190) -> 226451000 | O192: =SUMIF($A$6:$A$190,$A192,$O$6:$O$190) -> 82349000 | P192: =SUM(D192:O192) -> 2429130000
A193: 北三區 | C193: 合計 | D193: =SUMIF($A$6:$A$190,$A193,$D$6:$D$190) -> 211383000 | E193: =SUMIF($A$6:$A$190,$A193,$E$6:$E$190) -> 162607000 | F193: =SUMIF($A$6:$A$190,$A193,$F$6:$F$190) -> 162607000 | G193: =SUMIF($A$6:$A$190,$A193,$G$6:$G$190) -> 154469000 | H193: =SUMIF($A$6:$A$190,$A193,$H$6:$H$190) -> 178867000 | I193: =SUMIF($A$6:$A$190,$A193,$I$6:$I$190) -> 154469000 | J193: =SUMIF($A$6:$A$190,$A193,$J$6:$J$190) -> 154469000 | K193: =SUMIF($A$6:$A$190,$A193,$K$6:$K$190) -> 178867000 | L193: =SUMIF($A$6:$A$190,$A193,$L$6:$L$190) -> 154469000 | M193: =SUMIF($A$6:$A$190,$A193,$M$6:$M$190) -> 162607000 | N193: =SUMIF($A$6:$A$190,$A193,$N$6:$N$190) -> 178867000 | O193: =SUMIF($A$6:$A$190,$A193,$O$6:$O$190) -> 65029000 | P193: =SUM(D193:O193) -> 1918710000
A194: 中區 | C194: 合計 | D194: =SUMIF($A$6:$A$190,$A194,$D$6:$D$190) -> 241979000 | E194: =SUMIF($A$6:$A$190,$A194,$E$6:$E$190) -> 186139000 | F194: =SUMIF($A$6:$A$190,$A194,$F$6:$F$190) -> 186139000 | G194: =SUMIF($A$6:$A$190,$A194,$G$6:$G$190) -> 176828000 | H194: =SUMIF($A$6:$A$190,$A194,$H$6:$H$190) -> 204745000 | I194: =SUMIF($A$6:$A$190,$A194,$I$6:$I$190) -> 176828000 | J194: =SUMIF($A$6:$A$190,$A194,$J$6:$J$190) -> 176828000 | K194: =SUMIF($A$6:$A$190,$A194,$K$6:$K$190) -> 204745000 | L194: =SUMIF($A$6:$A$190,$A194,$L$6:$L$190) -> 176828000 | M194: =SUMIF($A$6:$A$190,$A194,$M$6:$M$190) -> 186139000 | N194: =SUMIF($A$6:$A$190,$A194,$N$6:$N$190) -> 204745000 | O194: =SUMIF($A$6:$A$190,$A194,$O$6:$O$190) -> 74487000 | P194: =SUM(D194:O194) -> 2196430000
A195: 南區 | C195: 合計 | D195: =SUMIF($A$6:$A$190,$A195,$D$6:$D$190) -> 251380000 | E195: =SUMIF($A$6:$A$190,$A195,$E$6:$E$190) -> 193370000 | F195: =SUMIF($A$6:$A$190,$A195,$F$6:$F$190) -> 193370000 | G195: =SUMIF($A$6:$A$190,$A195,$G$6:$G$190) -> 183699000 | H195: =SUMIF($A$6:$A$190,$A195,$H$6:$H$190) -> 212707000 | I195: =SUMIF($A$6:$A$190,$A195,$I$6:$I$190) -> 183699000 | J195: =SUMIF($A$6:$A$190,$A195,$J$6:$J$190) -> 183699000 | K195: =SUMIF($A$6:$A$190,$A195,$K$6:$K$190) -> 212707000 | L195: =SUMIF($A$6:$A$190,$A195,$L$6:$L$190) -> 183699000 | M195: =SUMIF($A$6:$A$190,$A195,$M$6:$M$190) -> 193370000 | N195: =SUMIF($A$6:$A$190,$A195,$N$6:$N$190) -> 212707000 | O195: =SUMIF($A$6:$A$190,$A195,$O$6:$O$190) -> 77343000 | P195: =SUM(D195:O195) -> 2281750000
A196: 總計 | D196: =SUM(D191:D195) -> 1299993000 | E196: =SUM(E191:E195) -> 1000000000 | F196: =SUM(F191:F195) -> 1000000000 | G196: =SUM(G191:G195) -> 949992000 | H196: =SUM(H191:H195) -> 1100004000 | I196: =SUM(I191:I195) -> 949992000 | J196: =SUM(J191:J195) -> 949992000 | K196: =SUM(K191:K195) -> 1100004000 | ... O196: =SUM(O191:O195) -> 400027000 | P196: =SUM(D196:O196) -> 11800000000

Sheet 客群經營各月
B1: 1 | C1: 2 | D1: 3 | E1: 4 | F1: 5 | G1: 6 | H1: 7 | I1: 8 | J1: 9 | K1: 10 | L1: 11 | M1: 12 | N1: 13 | O1: 14 | P1: 15
A2: 115年度各月營業單位客群經營目標表
P3: 單位：新臺幣元
A4: 通路中心 | B4: 單位 代號 | C4: 單位 名稱 | D4: 1月 | E4: 2月 | F4: 3月 | G4: 4月 | H4: 5月 | I4: 6月 | J4: 7月 | K4: 8月 | L4: 9月 | M4: 10月 | N4: 11月 | O4: 12月 | P4: 合計
D5: (A) | E5: (B) | F5: (C) | G5: (D) | H5: (E) | I5: (F) | J5: (G) | K5: (H) | L5: (I) | M5: (J) | N5: (K) | O5: (L) | P5: (M) = SUM(A:L)
A6: 北一區 | B6: 100 | C6: 營業部 | D6: =VLOOKUP(B6,財管手收各月!B:P, 3, 0) *0.55 -> 6291450 | E6: =VLOOKUP(B6,財管手收各月!B:P, 4, 0) *0.55 -> 4840000 | F6: =VLOOKUP(B6,財管手收各月!B:P, 5, 0) *0.55 -> 4840000 | G6: =VLOOKUP(B6,財管手收各月!B:P, 6, 0) *0.55 -> 4598550 | H6: =VLOOKUP(B6,財管手收各月!B:P, 7, 0) *0.55 -> 5324550 | I6: =VLOOKUP(B6,財管手收各月!B:P, 8, 0) *0.55 -> 4598550 | J6: =VLOOKUP(B6,財管手收各月!B:P, 9, 0) *0.55 -> 4598550 | K6: =VLOOKUP(B6,財管手收各月!B:P, 10, 0) *0.55 -> 5324550 | L6: =VLOOKUP(B6,財管手收各月!B:P, 11, 0) *0.55 -> 4598550 | M6: =VLOOKUP(B6,財管手收各月!B:P, 12, 0) *0.55 -> 4840000 | N6: =VLOOKUP(B6,財管手收各月!B:P, 13, 0) *0.55 -> 5324550 | O6: =VLOOKUP(B6,財管手收各月!B:P, 14, 0) *0.55 -> 1932700 | P6: =SUM(D6:O6) -> 57112000
A7: 北一區 | B7: 101 | C7: 儲蓄分行 | D7: =VLOOKUP(B7,財管手收各月!B:P, 3, 0) *0.55 -> 2177450 | E7: =VLOOKUP(B7,財管手收各月!B:P, 4, 0) *0.55 -> 1674750 | F7: =VLOOKUP(B7,財管手收各月!B:P, 5, 0) *0.55 -> 1674750 | G7: =VLOOKUP(B7,財管手收各月!B:P, 6, 0) *0.55 -> 1590600 | H7: =VLOOKUP(B7,財管手收各月!B:P, 7, 0) *0.55 -> 1841950 | I7: =VLOOKUP(B7,財管手收各月!B:P, 8, 0) *0.55 -> 1590600 | J7: =VLOOKUP(B7,財管手收各月!B:P, 9, 0) *0.55 -> 1590600 | K7: =VLOOKUP(B7,財管手收各月!B:P, 10, 0) *0.55 -> 1841950 | L7: =VLOOKUP(B7,財管手收各月!B:P, 11, 0) *0.55 -> 1590600 | M7: =VLOOKUP(B7,財管手收各月!B:P, 12, 0) *0.55 -> 1674750 | N7: =VLOOKUP(B7,財管手收各月!B:P, 13, 0) *0.55 -> 1841950 | O7: =VLOOKUP(B7,財管手收各月!B:P, 14, 0) *0.55 -> 671550 | P7: =SUM(D7:O7) -> 19761500
A8: 北一區 | B8: 103 | C8: 城內分行 | D8: =VLOOKUP(B8,財管手收各月!B:P, 3, 0) *0.55 -> 2679600 | E8: =VLOOKUP(B8,財管手收各月!B:P, 4, 0) *0.55 -> 2061400 | F8: =VLOOKUP(B8,財管手收各月!B:P, 5, 0) *0.55 -> 2061400 | G8: =VLOOKUP(B8,財管手收各月!B:P, 6, 0) *0.55 -> 1958000 | H8: =VLOOKUP(B8,財管手收各月!B:P, 7, 0) *0.55 -> 2267100 | I8: =VLOOKUP(B8,財管手收各月!B:P, 8, 0) *0.55 -> 1958000 | J8: =VLOOKUP(B8,財管手收各月!B:P, 9, 0) *0.55 -> 1958000 | K8: =VLOOKUP(B8,財管手收各月!B:P, 10, 0) *0.55 -> 2267100 | L8: =VLOOKUP(B8,財管手收各月!B:P, 11, 0) *0.55 -> 1958000 | M8: =VLOOKUP(B8,財管手收各月!B:P, 12, 0) *0.55 -> 2061400 | N8: =VLOOKUP(B8,財管手收各月!B:P, 13, 0) *0.55 -> 2267100 | O8: =VLOOKUP(B8,財管手收各月!B:P, 14, 0) *0.55 -> 823900 | P8: =SUM(D8:O8) -> 24321000
A9: 北一區 | B9: 104 | C9: 大稻埕分行 | D9: =VLOOKUP(B9,財管手收各月!B:P, 3, 0) *0.55 -> 4580400 | E9: =VLOOKUP(B9,財管手收各月!B:P, 4, 0) *0.55 -> 3523300 | F9: =VLOOKUP(B9,財管手收各月!B:P, 5, 0) *0.55 -> 3523300 | G9: =VLOOKUP(B9,財管手收各月!B:P, 6, 0) *0.55 -> 3347300 | H9: =VLOOKUP(B9,財管手收各月!B:P, 7, 0) *0.55 -> 3875850 | I9: =VLOOKUP(B9,財管手收各月!B:P, 8, 0) *0.55 -> 3347300 | J9: =VLOOKUP(B9,財管手收各月!B:P, 9, 0) *0.55 -> 3347300 | K9: =VLOOKUP(B9,財管手收各月!B:P, 10, 0) *0.55 -> 3875850 | L9: =VLOOKUP(B9,財管手收各月!B:P, 11, 0) *0.55 -> 3347300 | M9: =VLOOKUP(B9,財管手收各月!B:P, 12, 0) *0.55 -> 3523300 | N9: =VLOOKUP(B9,財管手收各月!B:P, 13, 0) *0.55 -> 3875850 | O9: =VLOOKUP(B9,財管手收各月!B:P, 14, 0) *0.55 -> 1407450 | P9: =SUM(D9:O9) -> 41574500
A10: 北一區 | B10: 105 | C10: 建成分行 | D10: =VLOOKUP(B10,財管手收各月!B:P, 3, 0) *0.55 -> 3462250 | E10: =VLOOKUP(B10,財管手收各月!B:P, 4, 0) *0.55 -> 2663650 | F10: =VLOOKUP(B10,財管手收各月!B:P, 5, 0) *0.55 -> 2663650 | G10: =VLOOKUP(B10,財管手收各月!B:P, 6, 0) *0.55 -> 2530550 | H10: =VLOOKUP(B10,財管手收各月!B:P, 7, 0) *0.55 -> 2929300 | I10: =VLOOKUP(B10,財管手收各月!B:P, 8, 0) *0.55 -> 2530550 | J10: =VLOOKUP(B10,財管手收各月!B:P, 9, 0) *0.55 -> 2530550 | K10: =VLOOKUP(B10,財管手收各月!B:P, 10, 0) *0.55 -> 2929300 | L10: =VLOOKUP(B10,財管手收各月!B:P, 11, 0) *0.55 -> 2530550 | M10: =VLOOKUP(B10,財管手收各月!B:P, 12, 0) *0.55 -> 2663650 | N10: =VLOOKUP(B10,財管手收各月!B:P, 13, 0) *0.55 -> 2929300 | O10: =VLOOKUP(B10,財管手收各月!B:P, 14, 0) *0.55 -> 1063700 | P10: =SUM(D10:O10) -> 31427000
A11: 北一區 | B11: 106 | C11: 中山分行 | D11: =VLOOKUP(B11,財管手收各月!B:P, 3, 0) *0.55 -> 6015350 | E11: =VLOOKUP(B11,財管手收各月!B:P, 4, 0) *0.55 -> 4627150 | F11: =VLOOKUP(B11,財管手收各月!B:P, 5, 0) *0.55 -> 4627150 | G11: =VLOOKUP(B11,財管手收各月!B:P, 6, 0) *0.55 -> 4396700 | H11: =VLOOKUP(B11,財管手收各月!B:P, 7, 0) *0.55 -> 5090250 | I11: =VLOOKUP(B11,財管手收各月!B:P, 8, 0) *0.55 -> 4396700 | J11: =VLOOKUP(B11,財管手收各月!B:P, 9, 0) *0.55 -> 4396700 | K11: =VLOOKUP(B11,財管手收各月!B:P, 10, 0) *0.55 -> 5090250 | L11: =VLOOKUP(B11,財管手收各月!B:P, 11, 0) *0.55 -> 4396700 | M11: =VLOOKUP(B11,財管手收各月!B:P, 12, 0) *0.55 -> 4627150 | N11: =VLOOKUP(B11,財管手收各月!B:P, 13, 0) *0.55 -> 5090250 | O11: =VLOOKUP(B11,財管手收各月!B:P, 14, 0) *0.55 -> 1849650 | P11: =SUM(D11:O11) -> 54604000
A12: 北一區 | B12: 107 | C12: 圓山分行 | D12: =VLOOKUP(B12,財管手收各月!B:P, 3, 0) *0.55 -> 7156050 | E12: =VLOOKUP(B12,財管手收各月!B:P, 4, 0) *0.55 -> 5504950 | F12: =VLOOKUP(B12,財管手收各月!B:P, 5, 0) *0.55 -> 5504950 | G12: =VLOOKUP(B12,財管手收各月!B:P, 6, 0) *0.55 -> 5229400 | H12: =VLOOKUP(B12,財管手收各月!B:P, 7, 0) *0.55 -> 6054950 | I12: =VLOOKUP(B12,財管手收各月!B:P, 8, 0) *0.55 -> 5229400 | J12: =VLOOKUP(B12,財管手收各月!B:P, 9, 0) *0.55 -> 5229400 | K12: =VLOOKUP(B12,財管手收各月!B:P, 10, 0) *0.55 -> 6054950 | L12: =VLOOKUP(B12,財管手收各月!B:P, 11, 0) *0.55 -> 5229400 | M12: =VLOOKUP(B12,財管手收各月!B:P, 12, 0) *0.55 -> 5504950 | N12: =VLOOKUP(B12,財管手收各月!B:P, 13, 0) *0.55 -> 6054950 | O12: =VLOOKUP(B12,財管手收各月!B:P, 14, 0) *0.55 -> 2201650 | P12: =SUM(D12:O12) -> 64955000
A13: 北一區 | B13: 108 | C13: 城東分行 | D13: =VLOOKUP(B13,財管手收各月!B:P, 3, 0) *0.55 -> 7755550 | E13: =VLOOKUP(B13,財管手收各月!B:P, 4, 0) *0.55 -> 5965850 | F13: =VLOOKUP(B13,財管手收各月!B:P, 5, 0) *0.55 -> 5965850 | G13: =VLOOKUP(B13,財管手收各月!B:P, 6, 0) *0.55 -> 5667750 | H13: =VLOOKUP(B13,財管手收各月!B:P, 7, 0) *0.55 -> 6562600 | I13: =VLOOKUP(B13,財管手收各月!B:P, 8, 0) *0.55 -> 5667750 | J13: =VLOOKUP(B13,財管手收各月!B:P, 9, 0) *0.55 -> 5667750 | K13: =VLOOKUP(B13,財管手收各月!B:P, 10, 0) *0.55 -> 6562600 | L13: =VLOOKUP(B13,財管手收各月!B:P, 11, 0) *0.55 -> 5667750 | M13: =VLOOKUP(B13,財管手收各月!B:P, 12, 0) *0.55 -> 5965850 | N13: =VLOOKUP(B13,財管手收各月!B:P, 13, 0) *0.55 -> 6562600 | O13: =VLOOKUP(B13,財管手收各月!B:P, 14, 0) *0.55 -> 2388100 | P13: =SUM(D13:O13) -> 70400000
A14: 北一區 | B14: 109 | C14: 西門分行 | D14: =VLOOKUP(B14,財管手收各月!B:P, 3, 0) *0.55 -> 2301200 | E14: =VLOOKUP(B14,財管手收各月!B:P, 4, 0) *0.55 -> 1770450 | F14: =VLOOKUP(B14,財管手收各月!B:P, 5, 0) *0.55 -> 1770450 | G14: =VLOOKUP(B14,財管手收各月!B:P, 6, 0) *0.55 -> 1681900 | H14: =VLOOKUP(B14,財管手收各月!B:P, 7, 0) *0.55 -> 1947000 | I14: =VLOOKUP(B14,財管手收各月!B:P, 8, 0) *0.55 -> 1681900 | J14: =VLOOKUP(B14,財管手收各月!B:P, 9, 0) *0.55 -> 1681900 | K14: =VLOOKUP(B14,財管手收各月!B:P, 10, 0) *0.55 -> 1947000 | L14: =VLOOKUP(B14,財管手收各月!B:P, 11, 0) *0.55 -> 1681900 | M14: =VLOOKUP(B14,財管手收各月!B:P, 12, 0) *0.55 -> 1770450 | N14: =VLOOKUP(B14,財管手收各月!B:P, 13, 0) *0.55 -> 1947000 | O14: =VLOOKUP(B14,財管手收各月!B:P, 14, 0) *0.55 -> 707850 | P14: =SUM(D14:O14) -> 20889000
A15: 北一區 | B15: 110 | C15: 南松山分行 | D15: =VLOOKUP(B15,財管手收各月!B:P, 3, 0) *0.55 -> 3604150 | E15: =VLOOKUP(B15,財管手收各月!B:P, 4, 0) *0.55 -> 2772000 | F15: =VLOOKUP(B15,財管手收各月!B:P, 5, 0) *0.55 -> 2772000 | G15: =VLOOKUP(B15,財管手收各月!B:P, 6, 0) *0.55 -> 2633950 | H15: =VLOOKUP(B15,財管手收各月!B:P, 7, 0) *0.55 -> 3049750 | I15: =VLOOKUP(B15,財管手收各月!B:P, 8, 0) *0.55 -> 2633950 | J15: =VLOOKUP(B15,財管手收各月!B:P, 9, 0) *0.55 -> 2633950 | K15: =VLOOKUP(B15,財管手收各月!B:P, 10, 0) *0.55 -> 3049750 | L15: =VLOOKUP(B15,財管手收各月!B:P, 11, 0) *0.55 -> 2633950 | M15: =VLOOKUP(B15,財管手收各月!B:P, 12, 0) *0.55 -> 2772000 | N15: =VLOOKUP(B15,財管手收各月!B:P, 13, 0) *0.55 -> 3049750 | O15: =VLOOKUP(B15,財管手收各月!B:P, 14, 0) *0.55 -> 1108800 | P15: =SUM(D15:O15) -> 32714000
A16: 北一區 | B16: 111 | C16: 仁愛路分行 | D16: =VLOOKUP(B16,財管手收各月!B:P, 3, 0) *0.55 -> 6170450 | E16: =VLOOKUP(B16,財管手收各月!B:P, 4, 0) *0.55 -> 4747050 | F16: =VLOOKUP(B16,財管手收各月!B:P, 5, 0) *0.55 -> 4747050 | G16: =VLOOKUP(B16,財管手收各月!B:P, 6, 0) *0.55 -> 4509450 | H16: =VLOOKUP(B16,財管手收各月!B:P, 7, 0) *0.55 -> 5221700 | I16: =VLOOKUP(B16,財管手收各月!B:P, 8, 0) *0.55 -> 4509450 | J16: =VLOOKUP(B16,財管手收各月!B:P, 9, 0) *0.55 -> 4509450 | K16: =VLOOKUP(B16,財管手收各月!B:P, 10, 0) *0.55 -> 5221700 | L16: =VLOOKUP(B16,財管手收各月!B:P, 11, 0) *0.55 -> 4509450 | M16: =VLOOKUP(B16,財管手收各月!B:P, 12, 0) *0.55 -> 4747050 | N16: =VLOOKUP(B16,財管手收各月!B:P, 13, 0) *0.55 -> 5221700 | O16: =VLOOKUP(B16,財管手收各月!B:P, 14, 0) *0.55 -> 1897500 | P16: =SUM(D16:O16) -> 56012000
A17: 北一區 | B17: 112 | C17: 南京東路分行 | D17: =VLOOKUP(B17,財管手收各月!B:P, 3, 0) *0.55 -> 4118950 | E17: =VLOOKUP(B17,財管手收各月!B:P, 4, 0) *0.55 -> 3167450 | F17: =VLOOKUP(B17,財管手收各月!B:P, 5, 0) *0.55 -> 3167450 | G17: =VLOOKUP(B17,財管手收各月!B:P, 6, 0) *0.55 -> 3009600 | H17: =VLOOKUP(B17,財管手收各月!B:P, 7, 0) *0.55 -> 3484250 | I17: =VLOOKUP(B17,財管手收各月!B:P, 8, 0) *0.55 -> 3009600 | J17: =VLOOKUP(B17,財管手收各月!B:P, 9, 0) *0.55 -> 3009600 | K17: =VLOOKUP(B17,財管手收各月!B:P, 10, 0) *0.55 -> 3484250 | L17: =VLOOKUP(B17,財管手收各月!B:P, 11, 0) *0.55 -> 3009600 | M17: =VLOOKUP(B17,財管手收各月!B:P, 12, 0) *0.55 -> 3167450 | N17: =VLOOKUP(B17,財管手收各月!B:P, 13, 0) *0.55 -> 3484250 | O17: =VLOOKUP(B17,財管手收各月!B:P, 14, 0) *0.55 -> 1271050 | P17: =SUM(D17:O17) -> 37383500
... A190: 北一區 | B190: 888 | C190: 營運總部分行 | D190: =VLOOKUP(B190,財管手收各月!B:P, 3, 0) *0.55 -> 1042250 | E190: =VLOOKUP(B190,財管手收各月!B:P, 4, 0) *0.55 -> 801350 | F190: =VLOOKUP(B190,財管手收各月!B:P, 5, 0) *0.55 -> 801350 | G190: =VLOOKUP(B190,財管手收各月!B:P, 6, 0) *0.55 -> 761750 | H190: =VLOOKUP(B190,財管手收各月!B:P, 7, 0) *0.55 -> 882200 | I190: =VLOOKUP(B190,財管手收各月!B:P, 8, 0) *0.55 -> 761750 | J190: =VLOOKUP(B190,財管手收各月!B:P, 9, 0) *0.55 -> 761750 | K190: =VLOOKUP(B190,財管手收各月!B:P, 10, 0) *0.55 -> 882200 | L190: =VLOOKUP(B190,財管手收各月!B:P, 11, 0) *0.55 -> 761750 | M190: =VLOOKUP(B190,財管手收各月!B:P, 12, 0) *0.55 -> 801350 | N190: =VLOOKUP(B190,財管手收各月!B:P, 13, 0) *0.55 -> 882200 | O190: =VLOOKUP(B190,財管手收各月!B:P, 14, 0) *0.55 -> 320100 | P190: =SUM(D190:O190) -> 9460000
A191: 北一區 | C191: 合計 | D191: =SUMIF($A$6:$A$190,$A191,$D$6:$D$190) -> 180202550 | E191: =SUMIF($A$6:$A$190,$A191,$E$6:$E$190) -> 138614300 | F191: =SUMIF($A$6:$A$190,$A191,$F$6:$F$190) -> 138614300 | G191: =SUMIF($A$6:$A$190,$A191,$G$6:$G$190) -> 131689250 | H191: =SUMIF($A$6:$A$190,$A191,$H$6:$H$190) -> 152478700 | I191: =SUMIF($A$6:$A$190,$A191,$I$6:$I$190) -> 131689250 | J191: =SUMIF($A$6:$A$190,$A191,$J$6:$J$190) -> 131689250 | K191: =SUMIF($A$6:$A$190,$A191,$K$6:$K$190) -> 152478700 | L191: =SUMIF($A$6:$A$190,$A191,$L$6:$L$190) -> 131689250 | M191: =SUMIF($A$6:$A$190,$A191,$M$6:$M$190) -> 138614300 | N191: =SUMIF($A$6:$A$190,$A191,$N$6:$N$190) -> 152478700 | O191: =SUMIF($A$6:$A$190,$A191,$O$6:$O$190) -> 55450450 | P191: =SUM(D191:O191) -> 1635689000
A192: 北二區 | C192: 合計 | D192: =SUMIF($A$6:$A$190,$A192,$D$6:$D$190) -> 147185500 | E192: =SUMIF($A$6:$A$190,$A192,$E$6:$E$190) -> 113221900 | F192: =SUMIF($A$6:$A$190,$A192,$F$6:$F$190) -> 113221900 | G192: =SUMIF($A$6:$A$190,$A192,$G$6:$G$190) -> 107558550 | H192: =SUMIF($A$6:$A$190,$A192,$H$6:$H$190) -> 124548050 | I192: =SUMIF($A$6:$A$190,$A192,$I$6:$I$190) -> 107558550 | J192: =SUMIF($A$6:$A$190,$A192,$J$6:$J$190) -> 107558550 | K192: =SUMIF($A$6:$A$190,$A192,$K$6:$K$190) -> 124548050 | L192: =SUMIF($A$6:$A$190,$A192,$L$6:$L$190) -> 107558550 | M192: =SUMIF($A$6:$A$190,$A192,$M$6:$M$190) -> 113221900 | N192: =SUMIF($A$6:$A$190,$A192,$N$6:$N$190) -> 124548050 | O192: =SUMIF($A$6:$A$190,$A192,$O$6:$O$190) -> 45291950 | P192: =SUM(D192:O192) -> 1336021500
A193: 北三區 | C193: 合計 | D193: =SUMIF($A$6:$A$190,$A193,$D$6:$D$190) -> 116260650 | E193: =SUMIF($A$6:$A$190,$A193,$E$6:$E$190) -> 89433850 | F193: =SUMIF($A$6:$A$190,$A193,$F$6:$F$190) -> 89433850 | G193: =SUMIF($A$6:$A$190,$A193,$G$6:$G$190) -> 84957950 | H193: =SUMIF($A$6:$A$190,$A193,$H$6:$H$190) -> 98376850 | I193: =SUMIF($A$6:$A$190,$A193,$I$6:$I$190) -> 84957950 | J193: =SUMIF($A$6:$A$190,$A193,$J$6:$J$190) -> 84957950 | K193: =SUMIF($A$6:$A$190,$A193,$K$6:$K$190) -> 98376850 | L193: =SUMIF($A$6:$A$190,$A193,$L$6:$L$190) -> 84957950 | M193: =SUMIF($A$6:$A$190,$A193,$M$6:$M$190) -> 89433850 | N193: =SUMIF($A$6:$A$190,$A193,$N$6:$N$190) -> 98376850 | O193: =SUMIF($A$6:$A$190,$A193,$O$6:$O$190) -> 35765950 | P193: =SUM(D193:O193) -> 1055290500
A194: 中區 | C194: 合計 | D194: =SUMIF($A$6:$A$190,$A194,$D$6:$D$190) -> 133088450 | E194: =SUMIF($A$6:$A$190,$A194,$E$6:$E$190) -> 102376450 | F194: =SUMIF($A$6:$A$190,$A194,$F$6:$F$190) -> 102376450 | G194: =SUMIF($A$6:$A$190,$A194,$G$6:$G$190) -> 97255400 | H194: =SUMIF($A$6:$A$190,$A194,$H$6:$H$190) -> 112609750 | I194: =SUMIF($A$6:$A$190,$A194,$I$6:$I$190) -> 97255400 | J194: =SUMIF($A$6:$A$190,$A194,$J$6:$J$190) -> 97255400 | K194: =SUMIF($A$6:$A$190,$A194,$K$6:$K$190) -> 112609750 | L194: =SUMIF($A$6:$A$190,$A194,$L$6:$L$190) -> 97255400 | M194: =SUMIF($A$6:$A$190,$A194,$M$6:$M$190) -> 102376450 | N194: =SUMIF($A$6:$A$190,$A194,$N$6:$N$190) -> 112609750 | O194: =SUMIF($A$6:$A$190,$A194,$O$6:$O$190) -> 40967850 | P194: =SUM(D194:O194) -> 1208036500
A195: 南區 | C195: 合計 | D195: =SUMIF($A$6:$A$190,$A195,$D$6:$D$190) -> 138259000 | E195: =SUMIF($A$6:$A$190,$A195,$E$6:$E$190) -> 106353500 | F195: =SUMIF($A$6:$A$190,$A195,$F$6:$F$190) -> 106353500 | G195: =SUMIF($A$6:$A$190,$A195,$G$6:$G$190) -> 101034450 | H195: =SUMIF($A$6:$A$190,$A195,$H$6:$H$190) -> 116988850 | I195: =SUMIF($A$6:$A$190,$A195,$I$6:$I$190) -> 101034450 | J195: =SUMIF($A$6:$A$190,$A195,$J$6:$J$190) -> 101034450 | K195: =SUMIF($A$6:$A$190,$A195,$K$6:$K$190) -> 116988850 | L195: =SUMIF($A$6:$A$190,$A195,$L$6:$L$190) -> 101034450 | M195: =SUMIF($A$6:$A$190,$A195,$M$6:$M$190) -> 106353500 | N195: =SUMIF($A$6:$A$190,$A195,$N$6:$N$190) -> 116988850 | O195: =SUMIF($A$6:$A$190,$A195,$O$6:$O$190) -> 42538650 | P195: =SUM(D195:O195) -> 1254962500
A196: 總計 | D196: =SUM(D191:D195) -> 714996150 | E196: =SUM(E191:E195) -> 550000000 | F196: =SUM(F191:F195) -> 550000000 | G196: =SUM(G191:G195) -> 522495600 | H196: =SUM(H191:H195) -> 605002200 | I196: =SUM(I191:I195) -> 522495600 | J196: =SUM(J191:J195) -> 522495600 | K196: =SUM(K191:K195) -> 605002200 | ... O196: =SUM(O191:O195) -> 220014850 | P196: =SUM(D196:O196) -> 6490000000

Sheet 全年KPI
B1: 1 | C1: 2 | D1: 3 | E1: 4 | F1: 5 | G1: 6 | H1: 7 | I1: 8 | J1: 11
A2: 115年度營業單位財富管理業務手續費收入目標表 | J2: 盈餘轉換率
I3: 單位：新臺幣元 | J3: =ROUND(I198, 4) -> 0.9608
A4: 通路中心 | B4: 單位 代號 | C4: 單位 名稱 | D4: 基金 手續費收入目標 | E4: 保險業務 手續費收入目標 | F4: 外國債券 手續費收入目標 | G4: 財產信託 手續費收入目標 | H4: 組合式商品 手續費收入目標 | I4: 財富管理 手續費收入目標 | J4: 財富管理手續費收入對盈餘目標之影響數
D5: (A) | E5: (B) | F5: (C) | G5: (D) | H5: (E) | I5: (F)=(A)+(B)+(C)+(D)+(E) | J5: (F)*0.9608
A6: 北一區 | B6: 100 | C6: 營業部 | D6: 26990000 | E6: 62090000 | F6: 7622000 | G6: 6049000 | H6: 1089000 | I6: =SUM(D6:H6) -> 103840000 | J6: =ROUND(I6*$J$3, -3) -> 99769000
A7: 北一區 | B7: 101 | C7: 儲蓄分行 | D7: 9340000 | E7: 21480000 | F7: 2358000 | G7: 2375000 | H7: 377000 | I7: =SUM(D7:H7) -> 35930000 | J7: =ROUND(I7*$J$3, -3) -> 34522000
A8: 北一區 | B8: 103 | C8: 城內分行 | D8: 11500000 | E8: 26440000 | F8: 3220000 | G8: 2596000 | H8: 464000 | I8: =SUM(D8:H8) -> 44220000 | J8: =ROUND(I8*$J$3, -3) -> 42487000
A9: 北一區 | B9: 104 | C9: 大稻埕分行 | D9: 19650000 | E9: 45200000 | F9: 5753000 | G9: 4194000 | H9: 793000 | I9: =SUM(D9:H9) -> 75590000 | J9: =ROUND(I9*$J$3, -3) -> 72627000
A10: 北一區 | B10: 105 | C10: 建成分行 | D10: 14850000 | E10: 34170000 | F10: 4056000 | G10: 3465000 | H10: 599000 | I10: =SUM(D10:H10) -> 57140000 | J10: =ROUND(I10*$J$3, -3) -> 54900000
A11: 北一區 | B11: 106 | C11: 中山分行 | D11: 25810000 | E11: 59370000 | F11: 7783000 | G11: 5276000 | H11: 1041000 | I11: =SUM(D11:H11) -> 99280000 | J11: =ROUND(I11*$J$3, -3) -> 95388000
A12: 北一區 | B12: 107 | C12: 圓山分行 | D12: 30700000 | E12: 70620000 | F12: 8774000 | G12: 6767000 | H12: 1239000 | I12: =SUM(D12:H12) -> 118100000 | J12: =ROUND(I12*$J$3, -3) -> 113470000
A13: 北一區 | B13: 108 | C13: 城東分行 | D13: 33270000 | E13: 76540000 | F13: 9791000 | G13: 7056000 | H13: 1343000 | I13: =SUM(D13:H13) -> 128000000 | J13: =ROUND(I13*$J$3, -3) -> 122982000
A14: 北一區 | B14: 109 | C14: 西門分行 | D14: 9870000 | E14: 22710000 | F14: 2933000 | G14: 2069000 | H14: 398000 | I14: =SUM(D14:H14) -> 37980000 | J14: =ROUND(I14*$J$3, -3) -> 36491000
A15: 北一區 | B15: 110 | C15: 南松山分行 | D15: 15460000 | E15: 35570000 | F15: 4588000 | G15: 3238000 | H15: 624000 | I15: =SUM(D15:H15) -> 59480000 | J15: =ROUND(I15*$J$3, -3) -> 57148000
A16: 北一區 | B16: 111 | C16: 仁愛路分行 | D16: 26470000 | E16: 60900000 | F16: 8081000 | G16: 5321000 | H16: 1068000 | I16: =SUM(D16:H16) -> 101840000 | J16: =ROUND(I16*$J$3, -3) -> 97848000
A17: 北一區 | B17: 112 | C17: 南京東路分行 | D17: 17670000 | E17: 40640000 | F17: 3850000 | G17: 5097000 | H17: 713000 | I17: =SUM(D17:H17) -> 67970000 | J17: =ROUND(I17*$J$3, -3) -> 65306000
... A190: 北一區 | B190: 888 | C190: 營運總部分行 | D190: 4470000 | E190: 10280000 | F190: 865000 | G190: 1405000 | H190: 180000 | I190: =SUM(D190:H190) -> 17200000 | J190: =ROUND(I190*$J$3, -3) -> 16526000
A191: 北一區 | C191: 合計 | D191: =SUMIF($A$6:$A$190,$A191,$D$6:$D$190) -> 773100000 | E191: =SUMIF($A$6:$A$190,$A191,$E$6:$E$190) -> 1778330000 | F191: =SUMIF($A$6:$A$190,$A191,$F$6:$F$190) -> 222412000 | G191: =SUMIF($A$6:$A$190,$A191,$G$6:$G$190) -> 168940000 | H191: =SUMIF($A$6:$A$190,$A191,$H$6:$H$190) -> 31198000 | I191: =SUM(D191:H191) -> 2973980000 | J191: =SUMIF($A$6:$A$190,$A191,$J$6:$J$190) -> 2857400000
A192: 北二區 | C192: 合計 | D192: =SUMIF($A$6:$A$190,$A192,$D$6:$D$190) -> 631440000 | E192: =SUMIF($A$6:$A$190,$A192,$E$6:$E$190) -> 1452500000 | F192: =SUMIF($A$6:$A$190,$A192,$F$6:$F$190) -> 189203000 | G192: =SUMIF($A$6:$A$190,$A192,$G$6:$G$190) -> 130507000 | H192: =SUMIF($A$6:$A$190,$A192,$H$6:$H$190) -> 25480000 | I192: =SUM(D192:H192) -> 2429130000 | J192: =SUMIF($A$6:$A$190,$A192,$J$6:$J$190) -> 2333907000
A193: 北三區 | C193: 合計 | D193: =SUMIF($A$6:$A$190,$A193,$D$6:$D$190) -> 498770000 | E193: =SUMIF($A$6:$A$190,$A193,$E$6:$E$190) -> 1147340000 | F193: =SUMIF($A$6:$A$190,$A193,$F$6:$F$190) -> 147109000 | G193: =SUMIF($A$6:$A$190,$A193,$G$6:$G$190) -> 105365000 | H193: =SUMIF($A$6:$A$190,$A193,$H$6:$H$190) -> 20126000 | I193: =SUM(D193:H193) -> 1918710000 | J193: =SUMIF($A$6:$A$190,$A193,$J$6:$J$190) -> 1843493000
A194: 中區 | C194: 合計 | D194: =SUMIF($A$6:$A$190,$A194,$D$6:$D$190) -> 570960000 | E194: =SUMIF($A$6:$A$190,$A194,$E$6:$E$190) -> 1313420000 | F194: =SUMIF($A$6:$A$190,$A194,$F$6:$F$190) -> 171582000 | G194: =SUMIF($A$6:$A$190,$A194,$G$6:$G$190) -> 117430000 | H194: =SUMIF($A$6:$A$190,$A194,$H$6:$H$190) -> 23038000 | I194: =SUM(D194:H194) -> 2196430000 | J194: =SUMIF($A$6:$A$190,$A194,$J$6:$J$190) -> 2110329000
A195: 南區 | C195: 合計 | D195: =SUMIF($A$6:$A$190,$A195,$D$6:$D$190) -> 593150000 | E195: =SUMIF($A$6:$A$190,$A195,$E$6:$E$190) -> 1364400000 | F195: =SUMIF($A$6:$A$190,$A195,$F$6:$F$190) -> 175495000 | G195: =SUMIF($A$6:$A$190,$A195,$G$6:$G$190) -> 124772000 | H195: =SUMIF($A$6:$A$190,$A195,$H$6:$H$190) -> 23933000 | I195: =SUM(D195:H195) -> 2281750000 | J195: =SUMIF($A$6:$A$190,$A195,$J$6:$J$190) -> 2192308000
A196: 總計 | D196: =SUM(D191:D195) -> 3067420000 | E196: =SUM(E191:E195) -> 7055990000 | F196: =SUM(F191:F195) -> 905801000 | G196: =SUM(G191:G195) -> 647014000 | H196: =SUM(H191:H195) -> 123775000 | I196: =SUM(I191:I195) -> 11800000000 | J196: =SUM(J191:J195) -> 11337437000
D197: =D196/$I$196 -> 0.25995085 | E197: =E196/$I$196 -> 0.59796525 | F197: =F196/$I$196 -> 0.076762797 | G197: =G196/$I$196 -> 0.054831695 | H197: =H196/$I$196 -> 0.010489407 | I197: 1
D198: 0.952 | E198: 0.9785 | F198: 0.9745 | G198: 0.9745 | H198: 0 | I198: =D197*D198+E197*E198+F197*F198+G197*G198+H197*H198 -> 0.96082104
C199: 年度 | D199: 109 | E199: 110 | F199: 111 | G199: 112 | H199: 113 | I199: 114
C200: 盈餘轉換率 | D200: 0.9348 | E200: 0.9462 | F200: 0.9503 | G200: 0.9512 | H200: 0.9587 | I200: 0.9608
B201: =(特定金錢信託佔率30.36%*XX年特定金錢信託平均補息率X%)+(人身保險佔率55.43%*補息率97.85%)+(外國債券佔率6.87%*補息率97.45%)+(財產信託佔率6.17%*補息率97.45%)

Sheet 115分組
A1: 分行代號 | B1: 分行名稱 | C1: 新組別 | D1: 115年組別 | E1: 參數 | F1: 組別目標 | I1: =ROUND(K1/P11/AVERAGE(I3:I10), 0)-9970 -> 109101 | K1: ='116年參數表'!C22 -> 21790000
A2: 100 | B2: 營業部 | C2: 第1組 | D2: 1 | E2: =VLOOKUP(D2,H:I,2,0) -> 1.7 | F2: =VLOOKUP(D2,H:K,4,0) -> 190000 | H2: 115年組別 | I2: 權重 | J2: 目標分配數 | K2: 目標分配數 | O2: 列標籤 | P2: 計數 - 分行代號
A3: 101 | B3: 儲蓄分行 | C3: 第3組 | D3: 3 | E3: =VLOOKUP(D3,H:I,2,0) -> 1.3 | F3: =VLOOKUP(D3,H:K,4,0) -> 150000 | H3: 1 | I3: 1.7 | J3: =_xlfn.CONCAT(K3/10000, "萬元") -> 19萬元 | K3: =ROUNDUP($I$1*I3, -4) -> 190000 | L3: =VLOOKUP(H3,O:P,2,0) -> 23 | M3: =K3*L3 -> 4370000 | O3: 1 | P3: 23
A4: 103 | B4: 城內分行 | C4: 第3組 | D4: 3 | E4: =VLOOKUP(D4,H:I,2,0) -> 1.3 | F4: =VLOOKUP(D4,H:K,4,0) -> 150000 | H4: 2 | I4: 1.5 | J4: =_xlfn.CONCAT(K4/10000, "萬元") -> 17萬元 | K4: =ROUNDUP($I$1*I4, -4) -> 170000 | L4: =VLOOKUP(H4,O:P,2,0) -> 23 | M4: =K4*L4 -> 3910000 | O4: 2 | P4: 23
A5: 104 | B5: 大稻埕分行 | C5: 第2組 | D5: 2 | E5: =VLOOKUP(D5,H:I,2,0) -> 1.5 | F5: =VLOOKUP(D5,H:K,4,0) -> 170000 | H5: 3 | I5: 1.3 | J5: =_xlfn.CONCAT(K5/10000, "萬元") -> 15萬元 | K5: =ROUNDUP($I$1*I5, -4) -> 150000 | L5: =VLOOKUP(H5,O:P,2,0) -> 23 | M5: =K5*L5 -> 3450000 | O5: 3 | P5: 23
A6: 105 | B6: 建成分行 | C6: 第1組 | D6: 1 | E6: =VLOOKUP(D6,H:I,2,0) -> 1.7 | F6: =VLOOKUP(D6,H:K,4,0) -> 190000 | H6: 4 | I6: 1.1 | J6: =_xlfn.CONCAT(K6/10000, "萬元") -> 13萬元 | K6: =ROUNDUP($I$1*I6, -4) -> 130000 | L6: =VLOOKUP(H6,O:P,2,0) -> 23 | M6: =K6*L6 -> 2990000 | O6: 4 | P6: 23
A7: 106 | B7: 中山分行 | C7: 第1組 | D7: 1 | E7: =VLOOKUP(D7,H:I,2,0) -> 1.7 | F7: =VLOOKUP(D7,H:K,4,0) -> 190000 | H7: 5 | I7: 0.9 | J7: =_xlfn.CONCAT(K7/10000, "萬元") -> 10萬元 | K7: =ROUNDUP($I$1*I7, -4) -> 100000 | L7: =VLOOKUP(H7,O:P,2,0) -> 23 | M7: =K7*L7 -> 2300000 | O7: 5 | P7: 23
A8: 107 | B8: 圓山分行 | C8: 第1組 | D8: 1 | E8: =VLOOKUP(D8,H:I,2,0) -> 1.7 | F8: =VLOOKUP(D8,H:K,4,0) -> 190000 | H8: 6 | I8: 0.7 | J8: =_xlfn.CONCAT(K8/10000, "萬元") -> 8萬元 | K8: =ROUNDUP($I$1*I8, -4) -> 80000 | L8: =VLOOKUP(H8,O:P,2,0) -> 23 | M8: =K8*L8 -> 1840000 | O8: 6 | P8: 23
A9: 108 | B9: 城東分行 | C9: 第1組 | D9: 1 | E9: =VLOOKUP(D9,H:I,2,0) -> 1.7 | F9: =VLOOKUP(D9,H:K,4,0) -> 190000 | H9: 7 | I9: 0.5 | J9: =_xlfn.CONCAT(K9/10000, "萬元") -> 6萬元 | K9: =ROUNDUP($I$1*I9, -4) -> 60000 | L9: =VLOOKUP(H9,O:P,2,0) -> 23 | M9: =K9*L9 -> 1380000 | O9: 7 | P9: 23
A10: 109 | B10: 西門分行 | C10: 第4組 | D10: 4 | E10: =VLOOKUP(D10,H:I,2,0) -> 1.1 | F10: =VLOOKUP(D10,H:K,4,0) -> 130000 | H10: 8 | I10: 0.3 | J10: =_xlfn.CONCAT(K10/10000, "萬元") -> 4萬元 | K10: =ROUNDUP($I$1*I10, -4) -> 40000 | L10: =VLOOKUP(H10,O:P,2,0) -> 22 | M10: =K10*L10 -> 880000 | O10: 8 | P10: 22
A11: 110 | B11: 南松山分行 | C11: 第5組 | D11: 5 | E11: =VLOOKUP(D11,H:I,2,0) -> 0.9 | F11: =VLOOKUP(D11,H:K,4,0) -> 100000 | K11: =SUM(K3:K10) -> 920000 | L11: =SUM(L3:L10) -> 183 | M11: =SUM(M3:M10) -> 21120000 | O11: 總計 | P11: 183
A12: 111 | B12: 仁愛路分行 | C12: 第1組 | D12: 1 | E12: =VLOOKUP(D12,H:I,2,0) -> 1.7 | F12: =VLOOKUP(D12,H:K,4,0) -> 190000 | M12: =K1-M11 -> 670000
A13: 112 | B13: 南京東路分行 | C13: 第1組 | D13: 1 | E13: =VLOOKUP(D13,H:I,2,0) -> 1.7 | F13: =VLOOKUP(D13,H:K,4,0) -> 190000
A14: 113 | B14: 新生分行 | C14: 第2組 | D14: 2 | E14: =VLOOKUP(D14,H:I,2,0) -> 1.5 | F14: =VLOOKUP(D14,H:K,4,0) -> 170000
A15: 114 | B15: 大同分行 | C15: 第3組 | D15: 3 | E15: =VLOOKUP(D15,H:I,2,0) -> 1.3 | F15: =VLOOKUP(D15,H:K,4,0) -> 150000
A16: 115 | B16: 松山分行 | C16: 第3組 | D16: 3 | E16: =VLOOKUP(D16,H:I,2,0) -> 1.3 | F16: =VLOOKUP(D16,H:K,4,0) -> 150000
A17: 116 | B17: 中崙分行 | C17: 第2組 | D17: 2 | E17: =VLOOKUP(D17,H:I,2,0) -> 1.5 | F17: =VLOOKUP(D17,H:K,4,0) -> 170000
A18: 117 | B18: 台北南門分行 | C18: 第1組 | D18: 1 | E18: =VLOOKUP(D18,H:I,2,0) -> 1.7 | F18: =VLOOKUP(D18,H:K,4,0) -> 190000
A19: 118 | B19: 公館分行 | C19: 第2組 | D19: 2 | E19: =VLOOKUP(D19,H:I,2,0) -> 1.5 | F19: =VLOOKUP(D19,H:K,4,0) -> 170000
A20: 119 | B20: 信義分行 | C20: 第5組 | D20: 5 | E20: =VLOOKUP(D20,H:I,2,0) -> 0.9 | F20: =VLOOKUP(D20,H:K,4,0) -> 100000
A21: 120 | B21: 忠孝東路分行 | C21: 第1組 | D21: 1 | E21: =VLOOKUP(D21,H:I,2,0) -> 1.7 | F21: =VLOOKUP(D21,H:K,4,0) -> 190000
A22: 121 | B22: 和平分行 | C22: 第3組 | D22: 3 | E22: =VLOOKUP(D22,H:I,2,0) -> 1.3 | F22: =VLOOKUP(D22,H:K,4,0) -> 150000
A23: 122 | B23: 雙園分行 | C23: 第3組 | D23: 3 | E23: =VLOOKUP(D23,H:I,2,0) -> 1.3 | F23: =VLOOKUP(D23,H:K,4,0) -> 150000
A24: 123 | B24: 士林分行 | C24: 第1組 | D24: 1 | E24: =VLOOKUP(D24,H:I,2,0) -> 1.7 | F24: =VLOOKUP(D24,H:K,4,0) -> 190000
... A189: 813 | B189: 佳冬分行 | C189: 第8組 | D189: 8 | E189: =VLOOKUP(D189,H:I,2,0) -> 0.3 | F189: =VLOOKUP(D189,H:K,4,0) -> 40000

Sheet 財管手收比較表_重點
A1: 116年度營業單位財富管理業務手續費收入目標訂定對照表 - 160億元版本重點呈報
P2: 單位:新臺幣元/%
A3: 類型 | B3: 序號 | C3: 通路中心 | D3: 單位代號 | E3: 單位名稱 | F3: 115年 年化達成率 | G3: 116年成長目標 原規則 計算公式 | H3: 116年成長目標 原規則 目標數(85%) | I3: 116年成長目標 調整規則 計算公式 | J3: 116年成長目標 調整規則 目標數(85%) | K3: 116年成長目標 調整規則 目標差異數 | L3: 116年綜合指標 目標數 (15%) | M3: 116年 目標 | N3: 115年 年中調整後目標 | O3: 115年 年化實績 | P3: 116年目標 較115年實績 成長率 | Q3: 116年目標 較115年目標 成長率 | R3: 115年 客群經營目標
F4: (A) | G4: (B) | H4: (C) | I4: (D) | J4: (E) | K4: (F)=(E-C) | L4: (G) | M4: (H)=(E+G) | N4: (I) | O4: (J) | P4: (K)=(H/J)-1 | Q4: (L)=(H/I)-1 | R4: (L)=(FX55%)
A5: 116年 目標 較115年 目標 成長率 排名 前20名 | B5: 159 | C5: =VLOOKUP(B5, '116目標底稿ver1'!B:AC, 2, 0) -> 南區 | D5: =VLOOKUP(B5, '116目標底稿ver1'!B:AC, 3, 0) -> 702 | E5: =VLOOKUP(B5, '116目標底稿ver1'!B:AC, 4, 0) -> 新興分行 | F5: =VLOOKUP(B5, '116目標底稿ver1'!B:AC, 9, 0) -> 2.14 | G5: =VLOOKUP(B5, '116目標底稿ver1'!B:AC, 12, 0) -> 預估實績*70% | H5: =VLOOKUP(B5, '116目標底稿ver1'!B:AC, 13, 0) -> 102680000 | I5: =VLOOKUP(B5, '116目標底稿ver1'!B:AC, 15, 0) -> 分行目標*120%*101% | J5: =VLOOKUP(B5, '116目標底稿ver1'!B:AC, 16, 0) -> 82890000 | K5: =VLOOKUP(B5, '116目標底稿ver1'!B:AC, 17, 0) -> -19790000 | L5: =VLOOKUP(B5, '116目標底稿ver1'!B:AC, 24, 0) -> 1700000 | M5: =J5+L5 -> 84590000 | N5: =VLOOKUP(B5, '116目標底稿ver1'!B:AC, 8, 0) -> 68390000 | O5: =VLOOKUP(B5, '116目標底稿ver1'!B:AC, 6, 0) -> 146683171 | P5: =M5/O5-1 -> -0.42331489 | Q5: =M5/N5-1 -> 0.23687674 | R5: =VLOOKUP(B5, '116目標底稿ver1'!B:AC, 28, 0) -> 46524500
B6: 67 | C6: =VLOOKUP(B6, '116目標底稿ver1'!B:AC, 2, 0) -> 北一區 | D6: =VLOOKUP(B6, '116目標底稿ver1'!B:AC, 3, 0) -> 178 | E6: =VLOOKUP(B6, '116目標底稿ver1'!B:AC, 4, 0) -> 北投分行 | F6: =VLOOKUP(B6, '116目標底稿ver1'!B:AC, 9, 0) -> 1.91 | G6: =VLOOKUP(B6, '116目標底稿ver1'!B:AC, 12, 0) -> 預估實績*80% | H6: =VLOOKUP(B6, '116目標底稿ver1'!B:AC, 13, 0) -> 105220000 | I6: =VLOOKUP(B6, '116目標底稿ver1'!B:AC, 15, 0) -> 分行目標*120%*101% | J6: =VLOOKUP(B6, '116目標底稿ver1'!B:AC, 16, 0) -> 83430000 | K6: =VLOOKUP(B6, '116目標底稿ver1'!B:AC, 17, 0) -> -21790000 | L6: =VLOOKUP(B6, '116目標底稿ver1'!B:AC, 24, 0) -> 2800000 | M6: =J6+L6 -> 86230000 | N6: =VLOOKUP(B6, '116目標底稿ver1'!B:AC, 8, 0) -> 68840000 | O6: =VLOOKUP(B6, '116目標底稿ver1'!B:AC, 6, 0) -> 131519728 | P6: =M6/O6-1 -> -0.34435692 | Q6: =M6/N6-1 -> 0.25261476 | R6: =VLOOKUP(B6, '116目標底稿ver1'!B:AC, 28, 0) -> 47426500
B7: 106 | C7: =VLOOKUP(B7, '116目標底稿ver1'!B:AC, 2, 0) -> 北三區 | D7: =VLOOKUP(B7, '116目標底稿ver1'!B:AC, 3, 0) -> 268 | E7: =VLOOKUP(B7, '116目標底稿ver1'!B:AC, 4, 0) -> 青埔分行 | F7: =VLOOKUP(B7, '116目標底稿ver1'!B:AC, 9, 0) -> 1.82 | G7: =VLOOKUP(B7, '116目標底稿ver1'!B:AC, 12, 0) -> 預估實績*80% | H7: =VLOOKUP(B7, '116目標底稿ver1'!B:AC, 13, 0) -> 30470000 | I7: =VLOOKUP(B7, '116目標底稿ver1'!B:AC, 15, 0) -> 分行目標*120%*101% | J7: =VLOOKUP(B7, '116目標底稿ver1'!B:AC, 16, 0) -> 25430000 | K7: =VLOOKUP(B7, '116目標底稿ver1'!B:AC, 17, 0) -> -5040000 | L7: =VLOOKUP(B7, '116目標底稿ver1'!B:AC, 24, 0) -> 670000 | M7: =J7+L7 -> 26100000 | N7: =VLOOKUP(B7, '116目標底稿ver1'!B:AC, 8, 0) -> 20980000 | O7: =VLOOKUP(B7, '116目標底稿ver1'!B:AC, 6, 0) -> 38092596 | P7: =M7/O7-1 -> -0.31482748 | Q7: =M7/N7-1 -> 0.24404194 | R7: =VLOOKUP(B7, '116目標底稿ver1'!B:AC, 28, 0) -> 14355000
B8: 155 | C8: =VLOOKUP(B8, '116目標底稿ver1'!B:AC, 2, 0) -> 南區 | D8: =VLOOKUP(B8, '116目標底稿ver1'!B:AC, 3, 0) -> 648 | E8: =VLOOKUP(B8, '116目標底稿ver1'!B:AC, 4, 0) -> 新市分行 | F8: =VLOOKUP(B8, '116目標底稿ver1'!B:AC, 9, 0) -> 1.34 | G8: =VLOOKUP(B8, '116目標底稿ver1'!B:AC, 12, 0) -> 預估實績*90% | H8: =VLOOKUP(B8, '116目標底稿ver1'!B:AC, 13, 0) -> 59810000 | I8: =VLOOKUP(B8, '116目標底稿ver1'!B:AC, 15, 0) -> 分行目標*120%*101% | J8: =VLOOKUP(B8, '116目標底稿ver1'!B:AC, 16, 0) -> 60310000 | K8: =VLOOKUP(B8, '116目標底稿ver1'!B:AC, 17, 0) -> 500000 | L8: =VLOOKUP(B8, '116目標底稿ver1'!B:AC, 24, 0) -> 1970000 | M8: =J8+L8 -> 62280000 | N8: =VLOOKUP(B8, '116目標底稿ver1'!B:AC, 8, 0) -> 49760000 | O8: =VLOOKUP(B8, '116目標底稿ver1'!B:AC, 6, 0) -> 66452314 | P8: =M8/O8-1 -> -0.062786587 | Q8: =M8/N8-1 -> 0.25160772 | R8: =VLOOKUP(B8, '116目標底稿ver1'!B:AC, 28, 0) -> 34254000
B9: 4 | C9: =VLOOKUP(B9, '116目標底稿ver1'!B:AC, 2, 0) -> 北一區 | D9: =VLOOKUP(B9, '116目標底稿ver1'!B:AC, 3, 0) -> 104 | E9: =VLOOKUP(B9, '116目標底稿ver1'!B:AC, 4, 0) -> 大稻埕分行 | F9: =VLOOKUP(B9, '116目標底稿ver1'!B:AC, 9, 0) -> 1.33 | G9: =VLOOKUP(B9, '116目標底稿ver1'!B:AC, 12, 0) -> 預估實績*90% | H9: =VLOOKUP(B9, '116目標底稿ver1'!B:AC, 13, 0) -> 90480000 | I9: =VLOOKUP(B9, '116目標底稿ver1'!B:AC, 15, 0) -> 分行目標*120%*101% | J9: =VLOOKUP(B9, '116目標底稿ver1'!B:AC, 16, 0) -> 91680000 | K9: =VLOOKUP(B9, '116目標底稿ver1'!B:AC, 17, 0) -> 1200000 | L9: =VLOOKUP(B9, '116目標底稿ver1'!B:AC, 24, 0) -> 2820000 | M9: =J9+L9 -> 94500000 | N9: =VLOOKUP(B9, '116目標底稿ver1'!B:AC, 8, 0) -> 75640000 | O9: =VLOOKUP(B9, '116目標底稿ver1'!B:AC, 6, 0) -> 100530724 | P9: =M9/O9-1 -> -0.059988865 | Q9: =M9/N9-1 -> 0.24933897 | R9: =VLOOKUP(B9, '116目標底稿ver1'!B:AC, 28, 0) -> 51975000
B10: 135 | C10: =VLOOKUP(B10, '116目標底稿ver1'!B:AC, 2, 0) -> 中區 | D10: =VLOOKUP(B10, '116目標底稿ver1'!B:AC, 3, 0) -> 521 | E10: =VLOOKUP(B10, '116目標底稿ver1'!B:AC, 4, 0) -> 和美分行 | F10: =VLOOKUP(B10, '116目標底稿ver1'!B:AC, 9, 0) -> 1.31 | G10: =VLOOKUP(B10, '116目標底稿ver1'!B:AC, 12, 0) -> 預估實績*90% | H10: =VLOOKUP(B10, '116目標底稿ver1'!B:AC, 13, 0) -> 139650000 | I10: =VLOOKUP(B10, '116目標底稿ver1'!B:AC, 15, 0) -> 分行目標*120%*101% | J10: =VLOOKUP(B10, '116目標底稿ver1'!B:AC, 16, 0) -> 143040000 | K10: =VLOOKUP(B10, '116目標底稿ver1'!B:AC, 17, 0) -> 3390000 | L10: =VLOOKUP(B10, '116目標底稿ver1'!B:AC, 24, 0) -> 4720000 | M10: =J10+L10 -> 147760000 | N10: =VLOOKUP(B10, '116目標底稿ver1'!B:AC, 8, 0) -> 118020000 | O10: =VLOOKUP(B10, '116目標底稿ver1'!B:AC, 6, 0) -> 155168611 | P10: =M10/O10-1 -> -0.047745552 | Q10: =M10/N10-1 -> 0.25199119 | R10: =VLOOKUP(B10, '116目標底稿ver1'!B:AC, 28, 0) -> 81268000
